Workbook

Sheet How to use
A1: How to use this workbook
A3: Legend
A4: Yellow cell, blue text | B4: You fill it in.
A5: Grey cell | B5: Formula. Don't edit.
A6: Orange cell | B6: Warning: GUI angle differs from Expected by >0.2° (wrong build/geometry/TCP), or error >1°.
A8: Before you start
A9: 1 | B9: Fill in Setup: date, build, battery voltage, and the calibration that is actually flashed (check arm 2).
A10: 2 | B10: Fresh batteries. Joint mode, 10% speed. Zero the protractor on the base plate.
A11: 3 | B11: Pick one flat face on each bicep and always measure on that face.
A13: Tests (in order)
A14: Sweep | B14: Up pass -730 → -570, then Down pass -570 → -730, 10 mm steps, no Home in between. 34 rows.
A15: Repeatability | B15: 3 points × 3 repeats, going Home between each.
A16: Off-axis | B16: Do this AFTER updating the calibration from the Analysis sheet. Checks pin order.
A18: At every point
A19: a | B19: Wait ~2 s to settle.
A20: b | B20: Optional: at the first couple of points, copy the GUI's angles into 'GUI cmd' to confirm they match Expected.
A21: c | B21: Measure each bicep with the protractor into 'Measured'. Positive = bicep DOWN from horizontal.
A23: Afterwards
A24: Analysis | B24: Gives slope/offset per arm, the corrected centre_us and us_per_deg, hysteresis and repeatability.
A25: Update | B25: Put the new values in delta_servo/config.h CAL[] AND robot_config.py, reflash, run pytest, then do Off-axis.
A27: Example row (format only, NOT real data; don't copy into Sweep)
A28: Pass | B28: Step | C28: x (mm) | D28: y (mm) | E28: Probe z (mm) | F28: Expected D9 (°) | G28: Expected D10 (°) | H28: Expected D11 (°) | I28: GUI cmd D9 (°) optional | J28: GUI cmd D10 (°) optional | K28: GUI cmd D11 (°) optional | L28: Measured D9 (°) | M28: Measured D10 (°) | N28: Measured D11 (°) | O28: Error D9 (°) | P28: Error D10 (°) | Q28: Error D11 (°)
A29: Up | B29: 1 | C29: 0 | D29: 0 | E29: -730 | F29: 35.44 | G29: 35.44 | H29: 35.44 | I29: 35.44 | J29: 35.44 | K29: 35.44 | L29: 35.9 | M29: 34.6 | N29: 35.5 | O29: 0.46 | P29: -0.84 | Q29: 0.06

Sheet Setup
A1: Delta robot joint-angle calibration test
A2: Yellow cells = you fill in. Grey cells = formulas, don't edit.
A4: Session
A5: Date
A6: Tester
A7: Firmware / GUI build (branch) | B7: claude/amazing-lovelace-onixrv
A8: Battery voltage at start (V)
A9: Battery voltage at end (V)
A10: Protractor zeroed on | B10: Base plate
A11: Bicep face measured
A13: Geometry (mm)
A14: SB base triangle side (servo shafts at side midpoints) | B14: 175 | C14: Source: delta_servo/config.h + robot_config.py (geometry confirmed by user 2026-09-30).
A15: SP ball-joint triangle side (joints at corners) | B15: 75
A16: L_UP bicep | B16: 177
A17: L_LO forearm | B17: 625
A18: TCP x offset (probe below platform) | B18: 0
A19: TCP y offset | B19: 0
A20: TCP z offset | B20: -21
A22: Derived (IK constants, same as deltarobot.py)
A23: wb = SB/(2*sqrt3) | B23: =B14/(2*SQRT(3)) -> 50.518149
A24: up = SP/sqrt3 | B24: =B15/SQRT(3) -> 43.30127
A25: wp = up/2 | B25: =B24/2 -> 21.650635
A26: a = wb - up | B26: =B23-B24 -> 7.2168784
A27: b = SP/2 - (sqrt3/2)*wb | B27: =B15/2-SQRT(3)/2*B23 -> -6.25
A28: c = wp - wb/2 | B28: =B25-B23/2 -> -3.6084392
A30: Calibration currently flashed (from config.h CAL[])
A31: Arm / pin | B31: centre_us | C31: us_per_deg | D31: dir | E31: Geometric slot
A32: D9 (arm 1) | B32: 1456 | C32: 9.8315 | D32: 1 | E32: 1
A33: D10 (arm 2) | B33: 1373 | C33: 9.7664 | D33: 1 | E33: 2
A34: D11 (arm 3) | B34: 1393 | C34: 9.6658 | D34: 1 | E34: 0
A36: Geometric slot = which IK arm position the pin drives (GEOM_TO_PHYS = [2,0,1]): slot 0 is on the model's -y axis. Used only for the expected-angle formulas.
A37: Corrections on the Analysis sheet assume dir = +1 (true for all three arms right now).
A39: Error to position conversion
A40: Probe z error per degree of bicep error (mm/deg), on-axis | B40: 3.1 | C40: Assumption: 3.0-3.2 mm/deg across z -730..-620 with this geometry (computed from IK); ~2.7 near -570.

Sheet Sweep
A1: Test 1: on-axis calibration sweep
A2: Joint mode, 10% speed. Pass Up: -730 to -570 in order, then Pass Down: -570 to -730. Do NOT return Home between points. Wait ~2 s at each point before measuring.
A3: Only Measured (protractor) is required. Error = measured - expected. GUI cmd is an optional spot check: orange = GUI differs from Expected by >0.2° (wrong build/geometry or wrong column).
A5: Pass | B5: Step | C5: x (mm) | D5: y (mm) | E5: Probe z (mm) | F5: Expected D9 (°) | G5: Expected D10 (°) | H5: Expected D11 (°) | I5: GUI cmd D9 (°) optional | J5: GUI cmd D10 (°) optional | K5: GUI cmd D11 (°) optional | L5: Measured D9 (°) | M5: Measured D10 (°) | N5: Measured D11 (°) | O5: Error D9 (°) | P5: Error D10 (°) | Q5: Error D11 (°) | R5: Notes
A6: Up | B6: 1 | C6: 0 | D6: 0 | E6: -730 | F6: =IF(OR(E6="",((-Setup!$B$16*(SQRT(3)*((C6-Setup!$B$18)+Setup!$B$27)+(D6-Setup!$B$19)+Setup!$B$28))^2+(2*(E6-Setup!$B$20)*Setup!$B$16)^2-(((C6-Setup!$B$18)^2+(D6-Setup!$B$19)^2+(E6-Setup!$B$20)^2)+Setup!$B$27^2+Setup!$B$28^2+Setup!$B$16^2+2*(C6-Setup!$B$18)*Setup!$B$27+2*(D6-Setup!$B$19)*Setup!$B$28-Setup!$B$17^2)^2)<0),"",DEGREES(2*ATAN((-(2*(E6-Setup!$B$20)*Setup!$B$16)-SQRT(((-Setup!$B$16*(SQRT(3)*((C6-Setup!$B$18)+Setup!$B$27)+(D6-Setup!$B$19)+Setup!$B$28))^2+(2*(E6-Setup!$B$20)*Setup!$B$16)^2-(((C6-Setup!$B$18)^2+(D6-Setup!$B$19)^2+(E6-Setup!$B$20)^2)+Setup!$B$27^2+Setup!$B$28^2+Setup!$B$16^2+2*(C6-Setup!$B$18)*Setup!$B$27+2*(D6-Setup!$B$19)*Setup!$B$28-Setup!$B$17^2)^2)))/((((C6-Setup!$B$18)^2+(D6-Setup!$B$19)^2+(E6-Setup!$B$20)^2)+Setup!$B$27^2+Setup!$B$28^2+Setup!$B$16^2+2*(C6-Setup!$B$18)*Setup!$B$27+2*(D6-Setup!$B$19)*Setup!$B$28-Setup!$B$17^2)-(-Setup!$B$16*(SQRT(3)*((C6-Setup!$B$18)+Setup!$B$27)+(D6-Setup!$B$19)+Setup!$B$28)))))) -> 35.435622 | G6: =IF(OR(E6="",((Setup!$B$16*(SQRT(3)*((C6-Setup!$B$18)-Setup!$B$27)-(D6-Setup!$B$19)-Setup!$B$28))^2+(2*(E6-Setup!$B$20)*Setup!$B$16)^2-(((C6-Setup!$B$18)^2+(D6-Setup!$B$19)^2+(E6-Setup!$B$20)^2)+Setup!$B$27^2+Setup!$B$28^2+Setup!$B$16^2-2*(C6-Setup!$B$18)*Setup!$B$27+2*(D6-Setup!$B$19)*Setup!$B$28-Setup!$B$17^2)^2)<0),"",DEGREES(2*ATAN((-(2*(E6-Setup!$B$20)*Setup!$B$16)-SQRT(((Setup!$B$16*(SQRT(3)*((C6-Setup!$B$18)-Setup!$B$27)-(D6-Setup!$B$19)-Setup!$B$28))^2+(2*(E6-Setup!$B$20)*Setup!$B$16)^2-(((C6-Setup!$B$18)^2+(D6-Setup!$B$19)^2+(E6-Setup!$B$20)^2)+Setup!$B$27^2+Setup!$B$28^2+Setup!$B$16^2-2*(C6-Setup!$B$18)*Setup!$B$27+2*(D6-Setup!$B$19)*Setup!$B$28-Setup!$B$17^2)^2)))/((((C6-Setup!$B$18)^2+(D6-Setup!$B$19)^2+(E6-Setup!$B$20)^2)+Setup!$B$27^2+Setup!$B$28^2+Setup!$B$16^2-2*(C6-Setup!$B$18)*Setup!$B$27+2*(D6-Setup!$B$19)*Setup!$B$28-Setup!$B$17^2)-(Setup!$B$16*(SQRT(3)*((C6-Setup!$B$18)-Setup!$B$27)-(D6-Setup!$B$19)-Setup!$B$28)))))) -> 35.435622 | H6: =IF(OR(E6="",((2*Setup!$B$16*((D6-Setup!$B$19)+Setup!$B$26))^2+(2*(E6-Setup!$B$20)*Setup!$B$16)^2-(((C6-Setup!$B$18)^2+(D6-Setup!$B$19)^2+(E6-Setup!$B$20)^2)+Setup!$B$26^2+Setup!$B$16^2+2*(D6-Setup!$B$19)*Setup!$B$26-Setup!$B$17^2)^2)<0),"",DEGREES(2*ATAN((-(2*(E6-Setup!$B$20)*Setup!$B$16)-SQRT(((2*Setup!$B$16*((D6-Setup!$B$19)+Setup!$B$26))^2+(2*(E6-Setup!$B$20)*Setup!$B$16)^2-(((C6-Setup!$B$18)^2+(D6-Setup!$B$19)^2+(E6-Setup!$B$20)^2)+Setup!$B$26^2+Setup!$B$16^2+2*(D6-Setup!$B$19)*Setup!$B$26-Setup!$B$17^2)^2)))/((((C6-Setup!$B$18)^2+(D6-Setup!$B$19)^2+(E6-Setup!$B$20)^2)+Setup!$B$26^2+Setup!$B$16^2+2*(D6-Setup!$B$19)*Setup!$B$26-Setup!$B$17^2)-(2*Setup!$B$16*((D6-Setup!$B$19)+Setup!$B$26)))))) -> 35.435622 | O6: =IF(OR(L6="",F6=""),"",L6-F6) | P6: =IF(OR(M6="",G6=""),"",M6-G6) | Q6: =IF(OR(N6="",H6=""),"",N6-H6)
A7: Up | B7: 2 | C7: 0 | D7: 0 | E7: -720 | F7: =IF(OR(E7="",((-Setup!$B$16*(SQRT(3)*((C7-Setup!$B$18)+Setup!$B$27)+(D7-Setup!$B$19)+Setup!$B$28))^2+(2*(E7-Setup!$B$20)*Setup!$B$16)^2-(((C7-Setup!$B$18)^2+(D7-Setup!$B$19)^2+(E7-Setup!$B$20)^2)+Setup!$B$27^2+Setup!$B$28^2+Setup!$B$16^2+2*(C7-Setup!$B$18)*Setup!$B$27+2*(D7-Setup!$B$19)*Setup!$B$28-Setup!$B$17^2)^2)<0),"",DEGREES(2*ATAN((-(2*(E7-Setup!$B$20)*Setup!$B$16)-SQRT(((-Setup!$B$16*(SQRT(3)*((C7-Setup!$B$18)+Setup!$B$27)+(D7-Setup!$B$19)+Setup!$B$28))^2+(2*(E7-Setup!$B$20)*Setup!$B$16)^2-(((C7-Setup!$B$18)^2+(D7-Setup!$B$19)^2+(E7-Setup!$B$20)^2)+Setup!$B$27^2+Setup!$B$28^2+Setup!$B$16^2+2*(C7-Setup!$B$18)*Setup!$B$27+2*(D7-Setup!$B$19)*Setup!$B$28-Setup!$B$17^2)^2)))/((((C7-Setup!$B$18)^2+(D7-Setup!$B$19)^2+(E7-Setup!$B$20)^2)+Setup!$B$27^2+Setup!$B$28^2+Setup!$B$16^2+2*(C7-Setup!$B$18)*Setup!$B$27+2*(D7-Setup!$B$19)*Setup!$B$28-Setup!$B$17^2)-(-Setup!$B$16*(SQRT(3)*((C7-Setup!$B$18)+Setup!$B$27)+(D7-Setup!$B$19)+Setup!$B$28)))))) -> 32.107832 | G7: =IF(OR(E7="",((Setup!$B$16*(SQRT(3)*((C7-Setup!$B$18)-Setup!$B$27)-(D7-Setup!$B$19)-Setup!$B$28))^2+(2*(E7-Setup!$B$20)*Setup!$B$16)^2-(((C7-Setup!$B$18)^2+(D7-Setup!$B$19)^2+(E7-Setup!$B$20)^2)+Setup!$B$27^2+Setup!$B$28^2+Setup!$B$16^2-2*(C7-Setup!$B$18)*Setup!$B$27+2*(D7-Setup!$B$19)*Setup!$B$28-Setup!$B$17^2)^2)<0),"",DEGREES(2*ATAN((-(2*(E7-Setup!$B$20)*Setup!$B$16)-SQRT(((Setup!$B$16*(SQRT(3)*((C7-Setup!$B$18)-Setup!$B$27)-(D7-Setup!$B$19)-Setup!$B$28))^2+(2*(E7-Setup!$B$20)*Setup!$B$16)^2-(((C7-Setup!$B$18)^2+(D7-Setup!$B$19)^2+(E7-Setup!$B$20)^2)+Setup!$B$27^2+Setup!$B$28^2+Setup!$B$16^2-2*(C7-Setup!$B$18)*Setup!$B$27+2*(D7-Setup!$B$19)*Setup!$B$28-Setup!$B$17^2)^2)))/((((C7-Setup!$B$18)^2+(D7-Setup!$B$19)^2+(E7-Setup!$B$20)^2)+Setup!$B$27^2+Setup!$B$28^2+Setup!$B$16^2-2*(C7-Setup!$B$18)*Setup!$B$27+2*(D7-Setup!$B$19)*Setup!$B$28-Setup!$B$17^2)-(Setup!$B$16*(SQRT(3)*((C7-Setup!$B$18)-Setup!$B$27)-(D7-Setup!$B$19)-Setup!$B$28)))))) -> 32.107832 | H7: =IF(OR(E7="",((2*Setup!$B$16*((D7-Setup!$B$19)+Setup!$B$26))^2+(2*(E7-Setup!$B$20)*Setup!$B$16)^2-(((C7-Setup!$B$18)^2+(D7-Setup!$B$19)^2+(E7-Setup!$B$20)^2)+Setup!$B$26^2+Setup!$B$16^2+2*(D7-Setup!$B$19)*Setup!$B$26-Setup!$B$17^2)^2)<0),"",DEGREES(2*ATAN((-(2*(E7-Setup!$B$20)*Setup!$B$16)-SQRT(((2*Setup!$B$16*((D7-Setup!$B$19)+Setup!$B$26))^2+(2*(E7-Setup!$B$20)*Setup!$B$16)^2-(((C7-Setup!$B$18)^2+(D7-Setup!$B$19)^2+(E7-Setup!$B$20)^2)+Setup!$B$26^2+Setup!$B$16^2+2*(D7-Setup!$B$19)*Setup!$B$26-Setup!$B$17^2)^2)))/((((C7-Setup!$B$18)^2+(D7-Setup!$B$19)^2+(E7-Setup!$B$20)^2)+Setup!$B$26^2+Setup!$B$16^2+2*(D7-Setup!$B$19)*Setup!$B$26-Setup!$B$17^2)-(2*Setup!$B$16*((D7-Setup!$B$19)+Setup!$B$26)))))) -> 32.107832 | O7: =IF(OR(L7="",F7=""),"",L7-F7) | P7: =IF(OR(M7="",G7=""),"",M7-G7) | Q7: =IF(OR(N7="",H7=""),"",N7-H7)
A8: Up | B8: 3 | C8: 0 | D8: 0 | E8: -710 | F8: =IF(OR(E8="",((-Setup!$B$16*(SQRT(3)*((C8-Setup!$B$18)+Setup!$B$27)+(D8-Setup!$B$19)+Setup!$B$28))^2+(2*(E8-Setup!$B$20)*Setup!$B$16)^2-(((C8-Setup!$B$18)^2+(D8-Setup!$B$19)^2+(E8-Setup!$B$20)^2)+Setup!$B$27^2+Setup!$B$28^2+Setup!$B$16^2+2*(C8-Setup!$B$18)*Setup!$B$27+2*(D8-Setup!$B$19)*Setup!$B$28-Setup!$B$17^2)^2)<0),"",DEGREES(2*ATAN((-(2*(E8-Setup!$B$20)*Setup!$B$16)-SQRT(((-Setup!$B$16*(SQRT(3)*((C8-Setup!$B$18)+Setup!$B$27)+(D8-Setup!$B$19)+Setup!$B$28))^2+(2*(E8-Setup!$B$20)*Setup!$B$16)^2-(((C8-Setup!$B$18)^2+(D8-Setup!$B$19)^2+(E8-Setup!$B$20)^2)+Setup!$B$27^2+Setup!$B$28^2+Setup!$B$16^2+2*(C8-Setup!$B$18)*Setup!$B$27+2*(D8-Setup!$B$19)*Setup!$B$28-Setup!$B$17^2)^2)))/((((C8-Setup!$B$18)^2+(D8-Setup!$B$19)^2+(E8-Setup!$B$20)^2)+Setup!$B$27^2+Setup!$B$28^2+Setup!$B$16^2+2*(C8-Setup!$B$18)*Setup!$B$27+2*(D8-Setup!$B$19)*Setup!$B$28-Setup!$B$17^2)-(-Setup!$B$16*(SQRT(3)*((C8-Setup!$B$18)+Setup!$B$27)+(D8-Setup!$B$19)+Setup!$B$28)))))) -> 28.85685 | G8: =IF(OR(E8="",((Setup!$B$16*(SQRT(3)*((C8-Setup!$B$18)-Setup!$B$27)-(D8-Setup!$B$19)-Setup!$B$28))^2+(2*(E8-Setup!$B$20)*Setup!$B$16)^2-(((C8-Setup!$B$18)^2+(D8-Setup!$B$19)^2+(E8-Setup!$B$20)^2)+Setup!$B$27^2+Setup!$B$28^2+Setup!$B$16^2-2*(C8-Setup!$B$18)*Setup!$B$27+2*(D8-Setup!$B$19)*Setup!$B$28-Setup!$B$17^2)^2)<0),"",DEGREES(2*ATAN((-(2*(E8-Setup!$B$20)*Setup!$B$16)-SQRT(((Setup!$B$16*(SQRT(3)*((C8-Setup!$B$18)-Setup!$B$27)-(D8-Setup!$B$19)-Setup!$B$28))^2+(2*(E8-Setup!$B$20)*Setup!$B$16)^2-(((C8-Setup!$B$18)^2+(D8-Setup!$B$19)^2+(E8-Setup!$B$20)^2)+Setup!$B$27^2+Setup!$B$28^2+Setup!$B$16^2-2*(C8-Setup!$B$18)*Setup!$B$27+2*(D8-Setup!$B$19)*Setup!$B$28-Setup!$B$17^2)^2)))/((((C8-Setup!$B$18)^2+(D8-Setup!$B$19)^2+(E8-Setup!$B$20)^2)+Setup!$B$27^2+Setup!$B$28^2+Setup!$B$16^2-2*(C8-Setup!$B$18)*Setup!$B$27+2*(D8-Setup!$B$19)*Setup!$B$28-Setup!$B$17^2)-(Setup!$B$16*(SQRT(3)*((C8-Setup!$B$18)-Setup!$B$27)-(D8-Setup!$B$19)-Setup!$B$28)))))) -> 28.85685 | H8: =IF(OR(E8="",((2*Setup!$B$16*((D8-Setup!$B$19)+Setup!$B$26))^2+(2*(E8-Setup!$B$20)*Setup!$B$16)^2-(((C8-Setup!$B$18)^2+(D8-Setup!$B$19)^2+(E8-Setup!$B$20)^2)+Setup!$B$26^2+Setup!$B$16^2+2*(D8-Setup!$B$19)*Setup!$B$26-Setup!$B$17^2)^2)<0),"",DEGREES(2*ATAN((-(2*(E8-Setup!$B$20)*Setup!$B$16)-SQRT(((2*Setup!$B$16*((D8-Setup!$B$19)+Setup!$B$26))^2+(2*(E8-Setup!$B$20)*Setup!$B$16)^2-(((C8-Setup!$B$18)^2+(D8-Setup!$B$19)^2+(E8-Setup!$B$20)^2)+Setup!$B$26^2+Setup!$B$16^2+2*(D8-Setup!$B$19)*Setup!$B$26-Setup!$B$17^2)^2)))/((((C8-Setup!$B$18)^2+(D8-Setup!$B$19)^2+(E8-Setup!$B$20)^2)+Setup!$B$26^2+Setup!$B$16^2+2*(D8-Setup!$B$19)*Setup!$B$26-Setup!$B$17^2)-(2*Setup!$B$16*((D8-Setup!$B$19)+Setup!$B$26)))))) -> 28.85685 | O8: =IF(OR(L8="",F8=""),"",L8-F8) | P8: =IF(OR(M8="",G8=""),"",M8-G8) | Q8: =IF(OR(N8="",H8=""),"",N8-H8)
A9: Up | B9: 4 | C9: 0 | D9: 0 | E9: -700 | F9: =IF(OR(E9="",((-Setup!$B$16*(SQRT(3)*((C9-Setup!$B$18)+Setup!$B$27)+(D9-Setup!$B$19)+Setup!$B$28))^2+(2*(E9-Setup!$B$20)*Setup!$B$16)^2-(((C9-Setup!$B$18)^2+(D9-Setup!$B$19)^2+(E9-Setup!$B$20)^2)+Setup!$B$27^2+Setup!$B$28^2+Setup!$B$16^2+2*(C9-Setup!$B$18)*Setup!$B$27+2*(D9-Setup!$B$19)*Setup!$B$28-Setup!$B$17^2)^2)<0),"",DEGREES(2*ATAN((-(2*(E9-Setup!$B$20)*Setup!$B$16)-SQRT(((-Setup!$B$16*(SQRT(3)*((C9-Setup!$B$18)+Setup!$B$27)+(D9-Setup!$B$19)+Setup!$B$28))^2+(2*(E9-Setup!$B$20)*Setup!$B$16)^2-(((C9-Setup!$B$18)^2+(D9-Setup!$B$19)^2+(E9-Setup!$B$20)^2)+Setup!$B$27^2+Setup!$B$28^2+Setup!$B$16^2+2*(C9-Setup!$B$18)*Setup!$B$27+2*(D9-Setup!$B$19)*Setup!$B$28-Setup!$B$17^2)^2)))/((((C9-Setup!$B$18)^2+(D9-Setup!$B$19)^2+(E9-Setup!$B$20)^2)+Setup!$B$27^2+Setup!$B$28^2+Setup!$B$16^2+2*(C9-Setup!$B$18)*Setup!$B$27+2*(D9-Setup!$B$19)*Setup!$B$28-Setup!$B$17^2)-(-Setup!$B$16*(SQRT(3)*((C9-Setup!$B$18)+Setup!$B$27)+(D9-Setup!$B$19)+Setup!$B$28)))))) -> 25.663746 | G9: =IF(OR(E9="",((Setup!$B$16*(SQRT(3)*((C9-Setup!$B$18)-Setup!$B$27)-(D9-Setup!$B$19)-Setup!$B$28))^2+(2*(E9-Setup!$B$20)*Setup!$B$16)^2-(((C9-Setup!$B$18)^2+(D9-Setup!$B$19)^2+(E9-Setup!$B$20)^2)+Setup!$B$27^2+Setup!$B$28^2+Setup!$B$16^2-2*(C9-Setup!$B$18)*Setup!$B$27+2*(D9-Setup!$B$19)*Setup!$B$28-Setup!$B$17^2)^2)<0),"",DEGREES(2*ATAN((-(2*(E9-Setup!$B$20)*Setup!$B$16)-SQRT(((Setup!$B$16*(SQRT(3)*((C9-Setup!$B$18)-Setup!$B$27)-(D9-Setup!$B$19)-Setup!$B$28))^2+(2*(E9-Setup!$B$20)*Setup!$B$16)^2-(((C9-Setup!$B$18)^2+(D9-Setup!$B$19)^2+(E9-Setup!$B$20)^2)+Setup!$B$27^2+Setup!$B$28^2+Setup!$B$16^2-2*(C9-Setup!$B$18)*Setup!$B$27+2*(D9-Setup!$B$19)*Setup!$B$28-Setup!$B$17^2)^2)))/((((C9-Setup!$B$18)^2+(D9-Setup!$B$19)^2+(E9-Setup!$B$20)^2)+Setup!$B$27^2+Setup!$B$28^2+Setup!$B$16^2-2*(C9-Setup!$B$18)*Setup!$B$27+2*(D9-Setup!$B$19)*Setup!$B$28-Setup!$B$17^2)-(Setup!$B$16*(SQRT(3)*((C9-Setup!$B$18)-Setup!$B$27)-(D9-Setup!$B$19)-Setup!$B$28)))))) -> 25.663746 | H9: =IF(OR(E9="",((2*Setup!$B$16*((D9-Setup!$B$19)+Setup!$B$26))^2+(2*(E9-Setup!$B$20)*Setup!$B$16)^2-(((C9-Setup!$B$18)^2+(D9-Setup!$B$19)^2+(E9-Setup!$B$20)^2)+Setup!$B$26^2+Setup!$B$16^2+2*(D9-Setup!$B$19)*Setup!$B$26-Setup!$B$17^2)^2)<0),"",DEGREES(2*ATAN((-(2*(E9-Setup!$B$20)*Setup!$B$16)-SQRT(((2*Setup!$B$16*((D9-Setup!$B$19)+Setup!$B$26))^2+(2*(E9-Setup!$B$20)*Setup!$B$16)^2-(((C9-Setup!$B$18)^2+(D9-Setup!$B$19)^2+(E9-Setup!$B$20)^2)+Setup!$B$26^2+Setup!$B$16^2+2*(D9-Setup!$B$19)*Setup!$B$26-Setup!$B$17^2)^2)))/((((C9-Setup!$B$18)^2+(D9-Setup!$B$19)^2+(E9-Setup!$B$20)^2)+Setup!$B$26^2+Setup!$B$16^2+2*(D9-Setup!$B$19)*Setup!$B$26-Setup!$B$17^2)-(2*Setup!$B$16*((D9-Setup!$B$19)+Setup!$B$26)))))) -> 25.663746 | O9: =IF(OR(L9="",F9=""),"",L9-F9) | P9: =IF(OR(M9="",G9=""),"",M9-G9) | Q9: =IF(OR(N9="",H9=""),"",N9-H9)
A10: Up | B10: 5 | C10: 0 | D10: 0 | E10: -690 | F10: =IF(OR(E10="",((-Setup!$B$16*(SQRT(3)*((C10-Setup!$B$18)+Setup!$B$27)+(D10-Setup!$B$19)+Setup!$B$28))^2+(2*(E10-Setup!$B$20)*Setup!$B$16)^2-(((C10-Setup!$B$18)^2+(D10-Setup!$B$19)^2+(E10-Setup!$B$20)^2)+Setup!$B$27^2+Setup!$B$28^2+Setup!$B$16^2+2*(C10-Setup!$B$18)*Setup!$B$27+2*(D10-Setup!$B$19)*Setup!$B$28-Setup!$B$17^2)^2)<0),"",DEGREES(2*ATAN((-(2*(E10-Setup!$B$20)*Setup!$B$16)-SQRT(((-Setup!$B$16*(SQRT(3)*((C10-Setup!$B$18)+Setup!$B$27)+(D10-Setup!$B$19)+Setup!$B$28))^2+(2*(E10-Setup!$B$20)*Setup!$B$16)^2-(((C10-Setup!$B$18)^2+(D10-Setup!$B$19)^2+(E10-Setup!$B$20)^2)+Setup!$B$27^2+Setup!$B$28^2+Setup!$B$16^2+2*(C10-Setup!$B$18)*Setup!$B$27+2*(D10-Setup!$B$19)*Setup!$B$28-Setup!$B$17^2)^2)))/((((C10-Setup!$B$18)^2+(D10-Setup!$B$19)^2+(E10-Setup!$B$20)^2)+Setup!$B$27^2+Setup!$B$28^2+Setup!$B$16^2+2*(C10-Setup!$B$18)*Setup!$B$27+2*(D10-Setup!$B$19)*Setup!$B$28-Setup!$B$17^2)-(-Setup!$B$16*(SQRT(3)*((C10-Setup!$B$18)+Setup!$B$27)+(D10-Setup!$B$19)+Setup!$B$28)))))) -> 22.512514 | G10: =IF(OR(E10="",((Setup!$B$16*(SQRT(3)*((C10-Setup!$B$18)-Setup!$B$27)-(D10-Setup!$B$19)-Setup!$B$28))^2+(2*(E10-Setup!$B$20)*Setup!$B$16)^2-(((C10-Setup!$B$18)^2+(D10-Setup!$B$19)^2+(E10-Setup!$B$20)^2)+Setup!$B$27^2+Setup!$B$28^2+Setup!$B$16^2-2*(C10-Setup!$B$18)*Setup!$B$27+2*(D10-Setup!$B$19)*Setup!$B$28-Setup!$B$17^2)^2)<0),"",DEGREES(2*ATAN((-(2*(E10-Setup!$B$20)*Setup!$B$16)-SQRT(((Setup!$B$16*(SQRT(3)*((C10-Setup!$B$18)-Setup!$B$27)-(D10-Setup!$B$19)-Setup!$B$28))^2+(2*(E10-Setup!$B$20)*Setup!$B$16)^2-(((C10-Setup!$B$18)^2+(D10-Setup!$B$19)^2+(E10-Setup!$B$20)^2)+Setup!$B$27^2+Setup!$B$28^2+Setup!$B$16^2-2*(C10-Setup!$B$18)*Setup!$B$27+2*(D10-Setup!$B$19)*Setup!$B$28-Setup!$B$17^2)^2)))/((((C10-Setup!$B$18)^2+(D10-Setup!$B$19)^2+(E10-Setup!$B$20)^2)+Setup!$B$27^2+Setup!$B$28^2+Setup!$B$16^2-2*(C10-Setup!$B$18)*Setup!$B$27+2*(D10-Setup!$B$19)*Setup!$B$28-Setup!$B$17^2)-(Setup!$B$16*(SQRT(3)*((C10-Setup!$B$18)-Setup!$B$27)-(D10-Setup!$B$19)-Setup!$B$28)))))) -> 22.512514 | H10: =IF(OR(E10="",((2*Setup!$B$16*((D10-Setup!$B$19)+Setup!$B$26))^2+(2*(E10-Setup!$B$20)*Setup!$B$16)^2-(((C10-Setup!$B$18)^2+(D10-Setup!$B$19)^2+(E10-Setup!$B$20)^2)+Setup!$B$26^2+Setup!$B$16^2+2*(D10-Setup!$B$19)*Setup!$B$26-Setup!$B$17^2)^2)<0),"",DEGREES(2*ATAN((-(2*(E10-Setup!$B$20)*Setup!$B$16)-SQRT(((2*Setup!$B$16*((D10-Setup!$B$19)+Setup!$B$26))^2+(2*(E10-Setup!$B$20)*Setup!$B$16)^2-(((C10-Setup!$B$18)^2+(D10-Setup!$B$19)^2+(E10-Setup!$B$20)^2)+Setup!$B$26^2+Setup!$B$16^2+2*(D10-Setup!$B$19)*Setup!$B$26-Setup!$B$17^2)^2)))/((((C10-Setup!$B$18)^2+(D10-Setup!$B$19)^2+(E10-Setup!$B$20)^2)+Setup!$B$26^2+Setup!$B$16^2+2*(D10-Setup!$B$19)*Setup!$B$26-Setup!$B$17^2)-(2*Setup!$B$16*((D10-Setup!$B$19)+Setup!$B$26)))))) -> 22.512514 | O10: =IF(OR(L10="",F10=""),"",L10-F10) | P10: =IF(OR(M10="",G10=""),"",M10-G10) | Q10: =IF(OR(N10="",H10=""),"",N10-H10)
A11: Up | B11: 6 | C11: 0 | D11: 0 | E11: -680 | F11: =IF(OR(E11="",((-Setup!$B$16*(SQRT(3)*((C11-Setup!$B$18)+Setup!$B$27)+(D11-Setup!$B$19)+Setup!$B$28))^2+(2*(E11-Setup!$B$20)*Setup!$B$16)^2-(((C11-Setup!$B$18)^2+(D11-Setup!$B$19)^2+(E11-Setup!$B$20)^2)+Setup!$B$27^2+Setup!$B$28^2+Setup!$B$16^2+2*(C11-Setup!$B$18)*Setup!$B$27+2*(D11-Setup!$B$19)*Setup!$B$28-Setup!$B$17^2)^2)<0),"",DEGREES(2*ATAN((-(2*(E11-Setup!$B$20)*Setup!$B$16)-SQRT(((-Setup!$B$16*(SQRT(3)*((C11-Setup!$B$18)+Setup!$B$27)+(D11-Setup!$B$19)+Setup!$B$28))^2+(2*(E11-Setup!$B$20)*Setup!$B$16)^2-(((C11-Setup!$B$18)^2+(D11-Setup!$B$19)^2+(E11-Setup!$B$20)^2)+Setup!$B$27^2+Setup!$B$28^2+Setup!$B$16^2+2*(C11-Setup!$B$18)*Setup!$B$27+2*(D11-Setup!$B$19)*Setup!$B$28-Setup!$B$17^2)^2)))/((((C11-Setup!$B$18)^2+(D11-Setup!$B$19)^2+(E11-Setup!$B$20)^2)+Setup!$B$27^2+Setup!$B$28^2+Setup!$B$16^2+2*(C11-Setup!$B$18)*Setup!$B$27+2*(D11-Setup!$B$19)*Setup!$B$28-Setup!$B$17^2)-(-Setup!$B$16*(SQRT(3)*((C11-Setup!$B$18)+Setup!$B$27)+(D11-Setup!$B$19)+Setup!$B$28)))))) -> 19.389174 | G11: =IF(OR(E11="",((Setup!$B$16*(SQRT(3)*((C11-Setup!$B$18)-Setup!$B$27)-(D11-Setup!$B$19)-Setup!$B$28))^2+(2*(E11-Setup!$B$20)*Setup!$B$16)^2-(((C11-Setup!$B$18)^2+(D11-Setup!$B$19)^2+(E11-Setup!$B$20)^2)+Setup!$B$27^2+Setup!$B$28^2+Setup!$B$16^2-2*(C11-Setup!$B$18)*Setup!$B$27+2*(D11-Setup!$B$19)*Setup!$B$28-Setup!$B$17^2)^2)<0),"",DEGREES(2*ATAN((-(2*(E11-Setup!$B$20)*Setup!$B$16)-SQRT(((Setup!$B$16*(SQRT(3)*((C11-Setup!$B$18)-Setup!$B$27)-(D11-Setup!$B$19)-Setup!$B$28))^2+(2*(E11-Setup!$B$20)*Setup!$B$16)^2-(((C11-Setup!$B$18)^2+(D11-Setup!$B$19)^2+(E11-Setup!$B$20)^2)+Setup!$B$27^2+Setup!$B$28^2+Setup!$B$16^2-2*(C11-Setup!$B$18)*Setup!$B$27+2*(D11-Setup!$B$19)*Setup!$B$28-Setup!$B$17^2)^2)))/((((C11-Setup!$B$18)^2+(D11-Setup!$B$19)^2+(E11-Setup!$B$20)^2)+Setup!$B$27^2+Setup!$B$28^2+Setup!$B$16^2-2*(C11-Setup!$B$18)*Setup!$B$27+2*(D11-Setup!$B$19)*Setup!$B$28-Setup!$B$17^2)-(Setup!$B$16*(SQRT(3)*((C11-Setup!$B$18)-Setup!$B$27)-(D11-Setup!$B$19)-Setup!$B$28)))))) -> 19.389174 | H11: =IF(OR(E11="",((2*Setup!$B$16*((D11-Setup!$B$19)+Setup!$B$26))^2+(2*(E11-Setup!$B$20)*Setup!$B$16)^2-(((C11-Setup!$B$18)^2+(D11-Setup!$B$19)^2+(E11-Setup!$B$20)^2)+Setup!$B$26^2+Setup!$B$16^2+2*(D11-Setup!$B$19)*Setup!$B$26-Setup!$B$17^2)^2)<0),"",DEGREES(2*ATAN((-(2*(E11-Setup!$B$20)*Setup!$B$16)-SQRT(((2*Setup!$B$16*((D11-Setup!$B$19)+Setup!$B$26))^2+(2*(E11-Setup!$B$20)*Setup!$B$16)^2-(((C11-Setup!$B$18)^2+(D11-Setup!$B$19)^2+(E11-Setup!$B$20)^2)+Setup!$B$26^2+Setup!$B$16^2+2*(D11-Setup!$B$19)*Setup!$B$26-Setup!$B$17^2)^2)))/((((C11-Setup!$B$18)^2+(D11-Setup!$B$19)^2+(E11-Setup!$B$20)^2)+Setup!$B$26^2+Setup!$B$16^2+2*(D11-Setup!$B$19)*Setup!$B$26-Setup!$B$17^2)-(2*Setup!$B$16*((D11-Setup!$B$19)+Setup!$B$26)))))) -> 19.389174 | O11: =IF(OR(L11="",F11=""),"",L11-F11) | P11: =IF(OR(M11="",G11=""),"",M11-G11) | Q11: =IF(OR(N11="",H11=""),"",N11-H11)
A12: Up | B12: 7 | C12: 0 | D12: 0 | E12: -670 | F12: =IF(OR(E12="",((-Setup!$B$16*(SQRT(3)*((C12-Setup!$B$18)+Setup!$B$27)+(D12-Setup!$B$19)+Setup!$B$28))^2+(2*(E12-Setup!$B$20)*Setup!$B$16)^2-(((C12-Setup!$B$18)^2+(D12-Setup!$B$19)^2+(E12-Setup!$B$20)^2)+Setup!$B$27^2+Setup!$B$28^2+Setup!$B$16^2+2*(C12-Setup!$B$18)*Setup!$B$27+2*(D12-Setup!$B$19)*Setup!$B$28-Setup!$B$17^2)^2)<0),"",DEGREES(2*ATAN((-(2*(E12-Setup!$B$20)*Setup!$B$16)-SQRT(((-Setup!$B$16*(SQRT(3)*((C12-Setup!$B$18)+Setup!$B$27)+(D12-Setup!$B$19)+Setup!$B$28))^2+(2*(E12-Setup!$B$20)*Setup!$B$16)^2-(((C12-Setup!$B$18)^2+(D12-Setup!$B$19)^2+(E12-Setup!$B$20)^2)+Setup!$B$27^2+Setup!$B$28^2+Setup!$B$16^2+2*(C12-Setup!$B$18)*Setup!$B$27+2*(D12-Setup!$B$19)*Setup!$B$28-Setup!$B$17^2)^2)))/((((C12-Setup!$B$18)^2+(D12-Setup!$B$19)^2+(E12-Setup!$B$20)^2)+Setup!$B$27^2+Setup!$B$28^2+Setup!$B$16^2+2*(C12-Setup!$B$18)*Setup!$B$27+2*(D12-Setup!$B$19)*Setup!$B$28-Setup!$B$17^2)-(-Setup!$B$16*(SQRT(3)*((C12-Setup!$B$18)+Setup!$B$27)+(D12-Setup!$B$19)+Setup!$B$28)))))) -> 16.281125 | G12: =IF(OR(E12="",((Setup!$B$16*(SQRT(3)*((C12-Setup!$B$18)-Setup!$B$27)-(D12-Setup!$B$19)-Setup!$B$28))^2+(2*(E12-Setup!$B$20)*Setup!$B$16)^2-(((C12-Setup!$B$18)^2+(D12-Setup!$B$19)^2+(E12-Setup!$B$20)^2)+Setup!$B$27^2+Setup!$B$28^2+Setup!$B$16^2-2*(C12-Setup!$B$18)*Setup!$B$27+2*(D12-Setup!$B$19)*Setup!$B$28-Setup!$B$17^2)^2)<0),"",DEGREES(2*ATAN((-(2*(E12-Setup!$B$20)*Setup!$B$16)-SQRT(((Setup!$B$16*(SQRT(3)*((C12-Setup!$B$18)-Setup!$B$27)-(D12-Setup!$B$19)-Setup!$B$28))^2+(2*(E12-Setup!$B$20)*Setup!$B$16)^2-(((C12-Setup!$B$18)^2+(D12-Setup!$B$19)^2+(E12-Setup!$B$20)^2)+Setup!$B$27^2+Setup!$B$28^2+Setup!$B$16^2-2*(C12-Setup!$B$18)*Setup!$B$27+2*(D12-Setup!$B$19)*Setup!$B$28-Setup!$B$17^2)^2)))/((((C12-Setup!$B$18)^2+(D12-Setup!$B$19)^2+(E12-Setup!$B$20)^2)+Setup!$B$27^2+Setup!$B$28^2+Setup!$B$16^2-2*(C12-Setup!$B$18)*Setup!$B$27+2*(D12-Setup!$B$19)*Setup!$B$28-Setup!$B$17^2)-(Setup!$B$16*(SQRT(3)*((C12-Setup!$B$18)-Setup!$B$27)-(D12-Setup!$B$19)-Setup!$B$28)))))) -> 16.281125 | H12: =IF(OR(E12="",((2*Setup!$B$16*((D12-Setup!$B$19)+Setup!$B$26))^2+(2*(E12-Setup!$B$20)*Setup!$B$16)^2-(((C12-Setup!$B$18)^2+(D12-Setup!$B$19)^2+(E12-Setup!$B$20)^2)+Setup!$B$26^2+Setup!$B$16^2+2*(D12-Setup!$B$19)*Setup!$B$26-Setup!$B$17^2)^2)<0),"",DEGREES(2*ATAN((-(2*(E12-Setup!$B$20)*Setup!$B$16)-SQRT(((2*Setup!$B$16*((D12-Setup!$B$19)+Setup!$B$26))^2+(2*(E12-Setup!$B$20)*Setup!$B$16)^2-(((C12-Setup!$B$18)^2+(D12-Setup!$B$19)^2+(E12-Setup!$B$20)^2)+Setup!$B$26^2+Setup!$B$16^2+2*(D12-Setup!$B$19)*Setup!$B$26-Setup!$B$17^2)^2)))/((((C12-Setup!$B$18)^2+(D12-Setup!$B$19)^2+(E12-Setup!$B$20)^2)+Setup!$B$26^2+Setup!$B$16^2+2*(D12-Setup!$B$19)*Setup!$B$26-Setup!$B$17^2)-(2*Setup!$B$16*((D12-Setup!$B$19)+Setup!$B$26)))))) -> 16.281125 | O12: =IF(OR(L12="",F12=""),"",L12-F12) | P12: =IF(OR(M12="",G12=""),"",M12-G12) | Q12: =IF(OR(N12="",H12=""),"",N12-H12)
A13: Up | B13: 8 | C13: 0 | D13: 0 | E13: -660 | F13: =IF(OR(E13="",((-Setup!$B$16*(SQRT(3)*((C13-Setup!$B$18)+Setup!$B$27)+(D13-Setup!$B$19)+Setup!$B$28))^2+(2*(E13-Setup!$B$20)*Setup!$B$16)^2-(((C13-Setup!$B$18)^2+(D13-Setup!$B$19)^2+(E13-Setup!$B$20)^2)+Setup!$B$27^2+Setup!$B$28^2+Setup!$B$16^2+2*(C13-Setup!$B$18)*Setup!$B$27+2*(D13-Setup!$B$19)*Setup!$B$28-Setup!$B$17^2)^2)<0),"",DEGREES(2*ATAN((-(2*(E13-Setup!$B$20)*Setup!$B$16)-SQRT(((-Setup!$B$16*(SQRT(3)*((C13-Setup!$B$18)+Setup!$B$27)+(D13-Setup!$B$19)+Setup!$B$28))^2+(2*(E13-Setup!$B$20)*Setup!$B$16)^2-(((C13-Setup!$B$18)^2+(D13-Setup!$B$19)^2+(E13-Setup!$B$20)^2)+Setup!$B$27^2+Setup!$B$28^2+Setup!$B$16^2+2*(C13-Setup!$B$18)*Setup!$B$27+2*(D13-Setup!$B$19)*Setup!$B$28-Setup!$B$17^2)^2)))/((((C13-Setup!$B$18)^2+(D13-Setup!$B$19)^2+(E13-Setup!$B$20)^2)+Setup!$B$27^2+Setup!$B$28^2+Setup!$B$16^2+2*(C13-Setup!$B$18)*Setup!$B$27+2*(D13-Setup!$B$19)*Setup!$B$28-Setup!$B$17^2)-(-Setup!$B$16*(SQRT(3)*((C13-Setup!$B$18)+Setup!$B$27)+(D13-Setup!$B$19)+Setup!$B$28)))))) -> 13.176654 | G13: =IF(OR(E13="",((Setup!$B$16*(SQRT(3)*((C13-Setup!$B$18)-Setup!$B$27)-(D13-Setup!$B$19)-Setup!$B$28))^2+(2*(E13-Setup!$B$20)*Setup!$B$16)^2-(((C13-Setup!$B$18)^2+(D13-Setup!$B$19)^2+(E13-Setup!$B$20)^2)+Setup!$B$27^2+Setup!$B$28^2+Setup!$B$16^2-2*(C13-Setup!$B$18)*Setup!$B$27+2*(D13-Setup!$B$19)*Setup!$B$28-Setup!$B$17^2)^2)<0),"",DEGREES(2*ATAN((-(2*(E13-Setup!$B$20)*Setup!$B$16)-SQRT(((Setup!$B$16*(SQRT(3)*((C13-Setup!$B$18)-Setup!$B$27)-(D13-Setup!$B$19)-Setup!$B$28))^2+(2*(E13-Setup!$B$20)*Setup!$B$16)^2-(((C13-Setup!$B$18)^2+(D13-Setup!$B$19)^2+(E13-Setup!$B$20)^2)+Setup!$B$27^2+Setup!$B$28^2+Setup!$B$16^2-2*(C13-Setup!$B$18)*Setup!$B$27+2*(D13-Setup!$B$19)*Setup!$B$28-Setup!$B$17^2)^2)))/((((C13-Setup!$B$18)^2+(D13-Setup!$B$19)^2+(E13-Setup!$B$20)^2)+Setup!$B$27^2+Setup!$B$28^2+Setup!$B$16^2-2*(C13-Setup!$B$18)*Setup!$B$27+2*(D13-Setup!$B$19)*Setup!$B$28-Setup!$B$17^2)-(Setup!$B$16*(SQRT(3)*((C13-Setup!$B$18)-Setup!$B$27)-(D13-Setup!$B$19)-Setup!$B$28)))))) -> 13.176654 | H13: =IF(OR(E13="",((2*Setup!$B$16*((D13-Setup!$B$19)+Setup!$B$26))^2+(2*(E13-Setup!$B$20)*Setup!$B$16)^2-(((C13-Setup!$B$18)^2+(D13-Setup!$B$19)^2+(E13-Setup!$B$20)^2)+Setup!$B$26^2+Setup!$B$16^2+2*(D13-Setup!$B$19)*Setup!$B$26-Setup!$B$17^2)^2)<0),"",DEGREES(2*ATAN((-(2*(E13-Setup!$B$20)*Setup!$B$16)-SQRT(((2*Setup!$B$16*((D13-Setup!$B$19)+Setup!$B$26))^2+(2*(E13-Setup!$B$20)*Setup!$B$16)^2-(((C13-Setup!$B$18)^2+(D13-Setup!$B$19)^2+(E13-Setup!$B$20)^2)+Setup!$B$26^2+Setup!$B$16^2+2*(D13-Setup!$B$19)*Setup!$B$26-Setup!$B$17^2)^2)))/((((C13-Setup!$B$18)^2+(D13-Setup!$B$19)^2+(E13-Setup!$B$20)^2)+Setup!$B$26^2+Setup!$B$16^2+2*(D13-Setup!$B$19)*Setup!$B$26-Setup!$B$17^2)-(2*Setup!$B$16*((D13-Setup!$B$19)+Setup!$B$26)))))) -> 13.176654 | O13: =IF(OR(L13="",F13=""),"",L13-F13) | P13: =IF(OR(M13="",G13=""),"",M13-G13) | Q13: =IF(OR(N13="",H13=""),"",N13-H13)
A14: Up | B14: 9 | C14: 0 | D14: 0 | E14: -650 | F14: =IF(OR(E14="",((-Setup!$B$16*(SQRT(3)*((C14-Setup!$B$18)+Setup!$B$27)+(D14-Setup!$B$19)+Setup!$B$28))^2+(2*(E14-Setup!$B$20)*Setup!$B$16)^2-(((C14-Setup!$B$18)^2+(D14-Setup!$B$19)^2+(E14-Setup!$B$20)^2)+Setup!$B$27^2+Setup!$B$28^2+Setup!$B$16^2+2*(C14-Setup!$B$18)*Setup!$B$27+2*(D14-Setup!$B$19)*Setup!$B$28-Setup!$B$17^2)^2)<0),"",DEGREES(2*ATAN((-(2*(E14-Setup!$B$20)*Setup!$B$16)-SQRT(((-Setup!$B$16*(SQRT(3)*((C14-Setup!$B$18)+Setup!$B$27)+(D14-Setup!$B$19)+Setup!$B$28))^2+(2*(E14-Setup!$B$20)*Setup!$B$16)^2-(((C14-Setup!$B$18)^2+(D14-Setup!$B$19)^2+(E14-Setup!$B$20)^2)+Setup!$B$27^2+Setup!$B$28^2+Setup!$B$16^2+2*(C14-Setup!$B$18)*Setup!$B$27+2*(D14-Setup!$B$19)*Setup!$B$28-Setup!$B$17^2)^2)))/((((C14-Setup!$B$18)^2+(D14-Setup!$B$19)^2+(E14-Setup!$B$20)^2)+Setup!$B$27^2+Setup!$B$28^2+Setup!$B$16^2+2*(C14-Setup!$B$18)*Setup!$B$27+2*(D14-Setup!$B$19)*Setup!$B$28-Setup!$B$17^2)-(-Setup!$B$16*(SQRT(3)*((C14-Setup!$B$18)+Setup!$B$27)+(D14-Setup!$B$19)+Setup!$B$28)))))) -> 10.064544 | G14: =IF(OR(E14="",((Setup!$B$16*(SQRT(3)*((C14-Setup!$B$18)-Setup!$B$27)-(D14-Setup!$B$19)-Setup!$B$28))^2+(2*(E14-Setup!$B$20)*Setup!$B$16)^2-(((C14-Setup!$B$18)^2+(D14-Setup!$B$19)^2+(E14-Setup!$B$20)^2)+Setup!$B$27^2+Setup!$B$28^2+Setup!$B$16^2-2*(C14-Setup!$B$18)*Setup!$B$27+2*(D14-Setup!$B$19)*Setup!$B$28-Setup!$B$17^2)^2)<0),"",DEGREES(2*ATAN((-(2*(E14-Setup!$B$20)*Setup!$B$16)-SQRT(((Setup!$B$16*(SQRT(3)*((C14-Setup!$B$18)-Setup!$B$27)-(D14-Setup!$B$19)-Setup!$B$28))^2+(2*(E14-Setup!$B$20)*Setup!$B$16)^2-(((C14-Setup!$B$18)^2+(D14-Setup!$B$19)^2+(E14-Setup!$B$20)^2)+Setup!$B$27^2+Setup!$B$28^2+Setup!$B$16^2-2*(C14-Setup!$B$18)*Setup!$B$27+2*(D14-Setup!$B$19)*Setup!$B$28-Setup!$B$17^2)^2)))/((((C14-Setup!$B$18)^2+(D14-Setup!$B$19)^2+(E14-Setup!$B$20)^2)+Setup!$B$27^2+Setup!$B$28^2+Setup!$B$16^2-2*(C14-Setup!$B$18)*Setup!$B$27+2*(D14-Setup!$B$19)*Setup!$B$28-Setup!$B$17^2)-(Setup!$B$16*(SQRT(3)*((C14-Setup!$B$18)-Setup!$B$27)-(D14-Setup!$B$19)-Setup!$B$28)))))) -> 10.064544 | H14: =IF(OR(E14="",((2*Setup!$B$16*((D14-Setup!$B$19)+Setup!$B$26))^2+(2*(E14-Setup!$B$20)*Setup!$B$16)^2-(((C14-Setup!$B$18)^2+(D14-Setup!$B$19)^2+(E14-Setup!$B$20)^2)+Setup!$B$26^2+Setup!$B$16^2+2*(D14-Setup!$B$19)*Setup!$B$26-Setup!$B$17^2)^2)<0),"",DEGREES(2*ATAN((-(2*(E14-Setup!$B$20)*Setup!$B$16)-SQRT(((2*Setup!$B$16*((D14-Setup!$B$19)+Setup!$B$26))^2+(2*(E14-Setup!$B$20)*Setup!$B$16)^2-(((C14-Setup!$B$18)^2+(D14-Setup!$B$19)^2+(E14-Setup!$B$20)^2)+Setup!$B$26^2+Setup!$B$16^2+2*(D14-Setup!$B$19)*Setup!$B$26-Setup!$B$17^2)^2)))/((((C14-Setup!$B$18)^2+(D14-Setup!$B$19)^2+(E14-Setup!$B$20)^2)+Setup!$B$26^2+Setup!$B$16^2+2*(D14-Setup!$B$19)*Setup!$B$26-Setup!$B$17^2)-(2*Setup!$B$16*((D14-Setup!$B$19)+Setup!$B$26)))))) -> 10.064544 | O14: =IF(OR(L14="",F14=""),"",L14-F14) | P14: =IF(OR(M14="",G14=""),"",M14-G14) | Q14: =IF(OR(N14="",H14=""),"",N14-H14)
A15: Up | B15: 10 | C15: 0 | D15: 0 | E15: -640 | F15: =IF(OR(E15="",((-Setup!$B$16*(SQRT(3)*((C15-Setup!$B$18)+Setup!$B$27)+(D15-Setup!$B$19)+Setup!$B$28))^2+(2*(E15-Setup!$B$20)*Setup!$B$16)^2-(((C15-Setup!$B$18)^2+(D15-Setup!$B$19)^2+(E15-Setup!$B$20)^2)+Setup!$B$27^2+Setup!$B$28^2+Setup!$B$16^2+2*(C15-Setup!$B$18)*Setup!$B$27+2*(D15-Setup!$B$19)*Setup!$B$28-Setup!$B$17^2)^2)<0),"",DEGREES(2*ATAN((-(2*(E15-Setup!$B$20)*Setup!$B$16)-SQRT(((-Setup!$B$16*(SQRT(3)*((C15-Setup!$B$18)+Setup!$B$27)+(D15-Setup!$B$19)+Setup!$B$28))^2+(2*(E15-Setup!$B$20)*Setup!$B$16)^2-(((C15-Setup!$B$18)^2+(D15-Setup!$B$19)^2+(E15-Setup!$B$20)^2)+Setup!$B$27^2+Setup!$B$28^2+Setup!$B$16^2+2*(C15-Setup!$B$18)*Setup!$B$27+2*(D15-Setup!$B$19)*Setup!$B$28-Setup!$B$17^2)^2)))/((((C15-Setup!$B$18)^2+(D15-Setup!$B$19)^2+(E15-Setup!$B$20)^2)+Setup!$B$27^2+Setup!$B$28^2+Setup!$B$16^2+2*(C15-Setup!$B$18)*Setup!$B$27+2*(D15-Setup!$B$19)*Setup!$B$28-Setup!$B$17^2)-(-Setup!$B$16*(SQRT(3)*((C15-Setup!$B$18)+Setup!$B$27)+(D15-Setup!$B$19)+Setup!$B$28)))))) -> 6.9337322 | G15: =IF(OR(E15="",((Setup!$B$16*(SQRT(3)*((C15-Setup!$B$18)-Setup!$B$27)-(D15-Setup!$B$19)-Setup!$B$28))^2+(2*(E15-Setup!$B$20)*Setup!$B$16)^2-(((C15-Setup!$B$18)^2+(D15-Setup!$B$19)^2+(E15-Setup!$B$20)^2)+Setup!$B$27^2+Setup!$B$28^2+Setup!$B$16^2-2*(C15-Setup!$B$18)*Setup!$B$27+2*(D15-Setup!$B$19)*Setup!$B$28-Setup!$B$17^2)^2)<0),"",DEGREES(2*ATAN((-(2*(E15-Setup!$B$20)*Setup!$B$16)-SQRT(((Setup!$B$16*(SQRT(3)*((C15-Setup!$B$18)-Setup!$B$27)-(D15-Setup!$B$19)-Setup!$B$28))^2+(2*(E15-Setup!$B$20)*Setup!$B$16)^2-(((C15-Setup!$B$18)^2+(D15-Setup!$B$19)^2+(E15-Setup!$B$20)^2)+Setup!$B$27^2+Setup!$B$28^2+Setup!$B$16^2-2*(C15-Setup!$B$18)*Setup!$B$27+2*(D15-Setup!$B$19)*Setup!$B$28-Setup!$B$17^2)^2)))/((((C15-Setup!$B$18)^2+(D15-Setup!$B$19)^2+(E15-Setup!$B$20)^2)+Setup!$B$27^2+Setup!$B$28^2+Setup!$B$16^2-2*(C15-Setup!$B$18)*Setup!$B$27+2*(D15-Setup!$B$19)*Setup!$B$28-Setup!$B$17^2)-(Setup!$B$16*(SQRT(3)*((C15-Setup!$B$18)-Setup!$B$27)-(D15-Setup!$B$19)-Setup!$B$28)))))) -> 6.9337322 | H15: =IF(OR(E15="",((2*Setup!$B$16*((D15-Setup!$B$19)+Setup!$B$26))^2+(2*(E15-Setup!$B$20)*Setup!$B$16)^2-(((C15-Setup!$B$18)^2+(D15-Setup!$B$19)^2+(E15-Setup!$B$20)^2)+Setup!$B$26^2+Setup!$B$16^2+2*(D15-Setup!$B$19)*Setup!$B$26-Setup!$B$17^2)^2)<0),"",DEGREES(2*ATAN((-(2*(E15-Setup!$B$20)*Setup!$B$16)-SQRT(((2*Setup!$B$16*((D15-Setup!$B$19)+Setup!$B$26))^2+(2*(E15-Setup!$B$20)*Setup!$B$16)^2-(((C15-Setup!$B$18)^2+(D15-Setup!$B$19)^2+(E15-Setup!$B$20)^2)+Setup!$B$26^2+Setup!$B$16^2+2*(D15-Setup!$B$19)*Setup!$B$26-Setup!$B$17^2)^2)))/((((C15-Setup!$B$18)^2+(D15-Setup!$B$19)^2+(E15-Setup!$B$20)^2)+Setup!$B$26^2+Setup!$B$16^2+2*(D15-Setup!$B$19)*Setup!$B$26-Setup!$B$17^2)-(2*Setup!$B$16*((D15-Setup!$B$19)+Setup!$B$26)))))) -> 6.9337322 | O15: =IF(OR(L15="",F15=""),"",L15-F15) | P15: =IF(OR(M15="",G15=""),"",M15-G15) | Q15: =IF(OR(N15="",H15=""),"",N15-H15)
A16: Up | B16: 11 | C16: 0 | D16: 0 | E16: -630 | F16: =IF(OR(E16="",((-Setup!$B$16*(SQRT(3)*((C16-Setup!$B$18)+Setup!$B$27)+(D16-Setup!$B$19)+Setup!$B$28))^2+(2*(E16-Setup!$B$20)*Setup!$B$16)^2-(((C16-Setup!$B$18)^2+(D16-Setup!$B$19)^2+(E16-Setup!$B$20)^2)+Setup!$B$27^2+Setup!$B$28^2+Setup!$B$16^2+2*(C16-Setup!$B$18)*Setup!$B$27+2*(D16-Setup!$B$19)*Setup!$B$28-Setup!$B$17^2)^2)<0),"",DEGREES(2*ATAN((-(2*(E16-Setup!$B$20)*Setup!$B$16)-SQRT(((-Setup!$B$16*(SQRT(3)*((C16-Setup!$B$18)+Setup!$B$27)+(D16-Setup!$B$19)+Setup!$B$28))^2+(2*(E16-Setup!$B$20)*Setup!$B$16)^2-(((C16-Setup!$B$18)^2+(D16-Setup!$B$19)^2+(E16-Setup!$B$20)^2)+Setup!$B$27^2+Setup!$B$28^2+Setup!$B$16^2+2*(C16-Setup!$B$18)*Setup!$B$27+2*(D16-Setup!$B$19)*Setup!$B$28-Setup!$B$17^2)^2)))/((((C16-Setup!$B$18)^2+(D16-Setup!$B$19)^2+(E16-Setup!$B$20)^2)+Setup!$B$27^2+Setup!$B$28^2+Setup!$B$16^2+2*(C16-Setup!$B$18)*Setup!$B$27+2*(D16-Setup!$B$19)*Setup!$B$28-Setup!$B$17^2)-(-Setup!$B$16*(SQRT(3)*((C16-Setup!$B$18)+Setup!$B$27)+(D16-Setup!$B$19)+Setup!$B$28)))))) -> 3.7729911 | G16: =IF(OR(E16="",((Setup!$B$16*(SQRT(3)*((C16-Setup!$B$18)-Setup!$B$27)-(D16-Setup!$B$19)-Setup!$B$28))^2+(2*(E16-Setup!$B$20)*Setup!$B$16)^2-(((C16-Setup!$B$18)^2+(D16-Setup!$B$19)^2+(E16-Setup!$B$20)^2)+Setup!$B$27^2+Setup!$B$28^2+Setup!$B$16^2-2*(C16-Setup!$B$18)*Setup!$B$27+2*(D16-Setup!$B$19)*Setup!$B$28-Setup!$B$17^2)^2)<0),"",DEGREES(2*ATAN((-(2*(E16-Setup!$B$20)*Setup!$B$16)-SQRT(((Setup!$B$16*(SQRT(3)*((C16-Setup!$B$18)-Setup!$B$27)-(D16-Setup!$B$19)-Setup!$B$28))^2+(2*(E16-Setup!$B$20)*Setup!$B$16)^2-(((C16-Setup!$B$18)^2+(D16-Setup!$B$19)^2+(E16-Setup!$B$20)^2)+Setup!$B$27^2+Setup!$B$28^2+Setup!$B$16^2-2*(C16-Setup!$B$18)*Setup!$B$27+2*(D16-Setup!$B$19)*Setup!$B$28-Setup!$B$17^2)^2)))/((((C16-Setup!$B$18)^2+(D16-Setup!$B$19)^2+(E16-Setup!$B$20)^2)+Setup!$B$27^2+Setup!$B$28^2+Setup!$B$16^2-2*(C16-Setup!$B$18)*Setup!$B$27+2*(D16-Setup!$B$19)*Setup!$B$28-Setup!$B$17^2)-(Setup!$B$16*(SQRT(3)*((C16-Setup!$B$18)-Setup!$B$27)-(D16-Setup!$B$19)-Setup!$B$28)))))) -> 3.7729911 | H16: =IF(OR(E16="",((2*Setup!$B$16*((D16-Setup!$B$19)+Setup!$B$26))^2+(2*(E16-Setup!$B$20)*Setup!$B$16)^2-(((C16-Setup!$B$18)^2+(D16-Setup!$B$19)^2+(E16-Setup!$B$20)^2)+Setup!$B$26^2+Setup!$B$16^2+2*(D16-Setup!$B$19)*Setup!$B$26-Setup!$B$17^2)^2)<0),"",DEGREES(2*ATAN((-(2*(E16-Setup!$B$20)*Setup!$B$16)-SQRT(((2*Setup!$B$16*((D16-Setup!$B$19)+Setup!$B$26))^2+(2*(E16-Setup!$B$20)*Setup!$B$16)^2-(((C16-Setup!$B$18)^2+(D16-Setup!$B$19)^2+(E16-Setup!$B$20)^2)+Setup!$B$26^2+Setup!$B$16^2+2*(D16-Setup!$B$19)*Setup!$B$26-Setup!$B$17^2)^2)))/((((C16-Setup!$B$18)^2+(D16-Setup!$B$19)^2+(E16-Setup!$B$20)^2)+Setup!$B$26^2+Setup!$B$16^2+2*(D16-Setup!$B$19)*Setup!$B$26-Setup!$B$17^2)-(2*Setup!$B$16*((D16-Setup!$B$19)+Setup!$B$26)))))) -> 3.7729911 | O16: =IF(OR(L16="",F16=""),"",L16-F16) | P16: =IF(OR(M16="",G16=""),"",M16-G16) | Q16: =IF(OR(N16="",H16=""),"",N16-H16)
A17: Up | B17: 12 | C17: 0 | D17: 0 | E17: -620 | F17: =IF(OR(E17="",((-Setup!$B$16*(SQRT(3)*((C17-Setup!$B$18)+Setup!$B$27)+(D17-Setup!$B$19)+Setup!$B$28))^2+(2*(E17-Setup!$B$20)*Setup!$B$16)^2-(((C17-Setup!$B$18)^2+(D17-Setup!$B$19)^2+(E17-Setup!$B$20)^2)+Setup!$B$27^2+Setup!$B$28^2+Setup!$B$16^2+2*(C17-Setup!$B$18)*Setup!$B$27+2*(D17-Setup!$B$19)*Setup!$B$28-Setup!$B$17^2)^2)<0),"",DEGREES(2*ATAN((-(2*(E17-Setup!$B$20)*Setup!$B$16)-SQRT(((-Setup!$B$16*(SQRT(3)*((C17-Setup!$B$18)+Setup!$B$27)+(D17-Setup!$B$19)+Setup!$B$28))^2+(2*(E17-Setup!$B$20)*Setup!$B$16)^2-(((C17-Setup!$B$18)^2+(D17-Setup!$B$19)^2+(E17-Setup!$B$20)^2)+Setup!$B$27^2+Setup!$B$28^2+Setup!$B$16^2+2*(C17-Setup!$B$18)*Setup!$B$27+2*(D17-Setup!$B$19)*Setup!$B$28-Setup!$B$17^2)^2)))/((((C17-Setup!$B$18)^2+(D17-Setup!$B$19)^2+(E17-Setup!$B$20)^2)+Setup!$B$27^2+Setup!$B$28^2+Setup!$B$16^2+2*(C17-Setup!$B$18)*Setup!$B$27+2*(D17-Setup!$B$19)*Setup!$B$28-Setup!$B$17^2)-(-Setup!$B$16*(SQRT(3)*((C17-Setup!$B$18)+Setup!$B$27)+(D17-Setup!$B$19)+Setup!$B$28)))))) -> 0.57060877 | G17: =IF(OR(E17="",((Setup!$B$16*(SQRT(3)*((C17-Setup!$B$18)-Setup!$B$27)-(D17-Setup!$B$19)-Setup!$B$28))^2+(2*(E17-Setup!$B$20)*Setup!$B$16)^2-(((C17-Setup!$B$18)^2+(D17-Setup!$B$19)^2+(E17-Setup!$B$20)^2)+Setup!$B$27^2+Setup!$B$28^2+Setup!$B$16^2-2*(C17-Setup!$B$18)*Setup!$B$27+2*(D17-Setup!$B$19)*Setup!$B$28-Setup!$B$17^2)^2)<0),"",DEGREES(2*ATAN((-(2*(E17-Setup!$B$20)*Setup!$B$16)-SQRT(((Setup!$B$16*(SQRT(3)*((C17-Setup!$B$18)-Setup!$B$27)-(D17-Setup!$B$19)-Setup!$B$28))^2+(2*(E17-Setup!$B$20)*Setup!$B$16)^2-(((C17-Setup!$B$18)^2+(D17-Setup!$B$19)^2+(E17-Setup!$B$20)^2)+Setup!$B$27^2+Setup!$B$28^2+Setup!$B$16^2-2*(C17-Setup!$B$18)*Setup!$B$27+2*(D17-Setup!$B$19)*Setup!$B$28-Setup!$B$17^2)^2)))/((((C17-Setup!$B$18)^2+(D17-Setup!$B$19)^2+(E17-Setup!$B$20)^2)+Setup!$B$27^2+Setup!$B$28^2+Setup!$B$16^2-2*(C17-Setup!$B$18)*Setup!$B$27+2*(D17-Setup!$B$19)*Setup!$B$28-Setup!$B$17^2)-(Setup!$B$16*(SQRT(3)*((C17-Setup!$B$18)-Setup!$B$27)-(D17-Setup!$B$19)-Setup!$B$28)))))) -> 0.57060877 | H17: =IF(OR(E17="",((2*Setup!$B$16*((D17-Setup!$B$19)+Setup!$B$26))^2+(2*(E17-Setup!$B$20)*Setup!$B$16)^2-(((C17-Setup!$B$18)^2+(D17-Setup!$B$19)^2+(E17-Setup!$B$20)^2)+Setup!$B$26^2+Setup!$B$16^2+2*(D17-Setup!$B$19)*Setup!$B$26-Setup!$B$17^2)^2)<0),"",DEGREES(2*ATAN((-(2*(E17-Setup!$B$20)*Setup!$B$16)-SQRT(((2*Setup!$B$16*((D17-Setup!$B$19)+Setup!$B$26))^2+(2*(E17-Setup!$B$20)*Setup!$B$16)^2-(((C17-Setup!$B$18)^2+(D17-Setup!$B$19)^2+(E17-Setup!$B$20)^2)+Setup!$B$26^2+Setup!$B$16^2+2*(D17-Setup!$B$19)*Setup!$B$26-Setup!$B$17^2)^2)))/((((C17-Setup!$B$18)^2+(D17-Setup!$B$19)^2+(E17-Setup!$B$20)^2)+Setup!$B$26^2+Setup!$B$16^2+2*(D17-Setup!$B$19)*Setup!$B$26-Setup!$B$17^2)-(2*Setup!$B$16*((D17-Setup!$B$19)+Setup!$B$26)))))) -> 0.57060877 | O17: =IF(OR(L17="",F17=""),"",L17-F17) | P17: =IF(OR(M17="",G17=""),"",M17-G17) | Q17: =IF(OR(N17="",H17=""),"",N17-H17)
... A39: Down | B39: 17 | C39: 0 | D39: 0 | E39: -730 | F39: =IF(OR(E39="",((-Setup!$B$16*(SQRT(3)*((C39-Setup!$B$18)+Setup!$B$27)+(D39-Setup!$B$19)+Setup!$B$28))^2+(2*(E39-Setup!$B$20)*Setup!$B$16)^2-(((C39-Setup!$B$18)^2+(D39-Setup!$B$19)^2+(E39-Setup!$B$20)^2)+Setup!$B$27^2+Setup!$B$28^2+Setup!$B$16^2+2*(C39-Setup!$B$18)*Setup!$B$27+2*(D39-Setup!$B$19)*Setup!$B$28-Setup!$B$17^2)^2)<0),"",DEGREES(2*ATAN((-(2*(E39-Setup!$B$20)*Setup!$B$16)-SQRT(((-Setup!$B$16*(SQRT(3)*((C39-Setup!$B$18)+Setup!$B$27)+(D39-Setup!$B$19)+Setup!$B$28))^2+(2*(E39-Setup!$B$20)*Setup!$B$16)^2-(((C39-Setup!$B$18)^2+(D39-Setup!$B$19)^2+(E39-Setup!$B$20)^2)+Setup!$B$27^2+Setup!$B$28^2+Setup!$B$16^2+2*(C39-Setup!$B$18)*Setup!$B$27+2*(D39-Setup!$B$19)*Setup!$B$28-Setup!$B$17^2)^2)))/((((C39-Setup!$B$18)^2+(D39-Setup!$B$19)^2+(E39-Setup!$B$20)^2)+Setup!$B$27^2+Setup!$B$28^2+Setup!$B$16^2+2*(C39-Setup!$B$18)*Setup!$B$27+2*(D39-Setup!$B$19)*Setup!$B$28-Setup!$B$17^2)-(-Setup!$B$16*(SQRT(3)*((C39-Setup!$B$18)+Setup!$B$27)+(D39-Setup!$B$19)+Setup!$B$28)))))) -> 35.435622 | G39: =IF(OR(E39="",((Setup!$B$16*(SQRT(3)*((C39-Setup!$B$18)-Setup!$B$27)-(D39-Setup!$B$19)-Setup!$B$28))^2+(2*(E39-Setup!$B$20)*Setup!$B$16)^2-(((C39-Setup!$B$18)^2+(D39-Setup!$B$19)^2+(E39-Setup!$B$20)^2)+Setup!$B$27^2+Setup!$B$28^2+Setup!$B$16^2-2*(C39-Setup!$B$18)*Setup!$B$27+2*(D39-Setup!$B$19)*Setup!$B$28-Setup!$B$17^2)^2)<0),"",DEGREES(2*ATAN((-(2*(E39-Setup!$B$20)*Setup!$B$16)-SQRT(((Setup!$B$16*(SQRT(3)*((C39-Setup!$B$18)-Setup!$B$27)-(D39-Setup!$B$19)-Setup!$B$28))^2+(2*(E39-Setup!$B$20)*Setup!$B$16)^2-(((C39-Setup!$B$18)^2+(D39-Setup!$B$19)^2+(E39-Setup!$B$20)^2)+Setup!$B$27^2+Setup!$B$28^2+Setup!$B$16^2-2*(C39-Setup!$B$18)*Setup!$B$27+2*(D39-Setup!$B$19)*Setup!$B$28-Setup!$B$17^2)^2)))/((((C39-Setup!$B$18)^2+(D39-Setup!$B$19)^2+(E39-Setup!$B$20)^2)+Setup!$B$27^2+Setup!$B$28^2+Setup!$B$16^2-2*(C39-Setup!$B$18)*Setup!$B$27+2*(D39-Setup!$B$19)*Setup!$B$28-Setup!$B$17^2)-(Setup!$B$16*(SQRT(3)*((C39-Setup!$B$18)-Setup!$B$27)-(D39-Setup!$B$19)-Setup!$B$28)))))) -> 35.435622 | H39: =IF(OR(E39="",((2*Setup!$B$16*((D39-Setup!$B$19)+Setup!$B$26))^2+(2*(E39-Setup!$B$20)*Setup!$B$16)^2-(((C39-Setup!$B$18)^2+(D39-Setup!$B$19)^2+(E39-Setup!$B$20)^2)+Setup!$B$26^2+Setup!$B$16^2+2*(D39-Setup!$B$19)*Setup!$B$26-Setup!$B$17^2)^2)<0),"",DEGREES(2*ATAN((-(2*(E39-Setup!$B$20)*Setup!$B$16)-SQRT(((2*Setup!$B$16*((D39-Setup!$B$19)+Setup!$B$26))^2+(2*(E39-Setup!$B$20)*Setup!$B$16)^2-(((C39-Setup!$B$18)^2+(D39-Setup!$B$19)^2+(E39-Setup!$B$20)^2)+Setup!$B$26^2+Setup!$B$16^2+2*(D39-Setup!$B$19)*Setup!$B$26-Setup!$B$17^2)^2)))/((((C39-Setup!$B$18)^2+(D39-Setup!$B$19)^2+(E39-Setup!$B$20)^2)+Setup!$B$26^2+Setup!$B$16^2+2*(D39-Setup!$B$19)*Setup!$B$26-Setup!$B$17^2)-(2*Setup!$B$16*((D39-Setup!$B$19)+Setup!$B$26)))))) -> 35.435622 | O39: =IF(OR(L39="",F39=""),"",L39-F39) | P39: =IF(OR(M39="",G39=""),"",M39-G39) | Q39: =IF(OR(N39="",H39=""),"",N39-H39)

Sheet Repeatability
A1: Test 1b: repeatability
A2: After the sweep: go Home, then to the point; measure; back Home; repeat 3x per point. Always approach from Home.
A3: Only Measured (protractor) is required. Error = measured - expected. GUI cmd is an optional spot check: orange = GUI differs from Expected by >0.2° (wrong build/geometry or wrong column).
A5: Repeat | B5: Step | C5: x (mm) | D5: y (mm) | E5: Probe z (mm) | F5: Expected D9 (°) | G5: Expected D10 (°) | H5: Expected D11 (°) | I5: GUI cmd D9 (°) optional | J5: GUI cmd D10 (°) optional | K5: GUI cmd D11 (°) optional | L5: Measured D9 (°) | M5: Measured D10 (°) | N5: Measured D11 (°) | O5: Error D9 (°) | P5: Error D10 (°) | Q5: Error D11 (°) | R5: Notes
A6: Rep 1 | B6: 1 | C6: 0 | D6: 0 | E6: -730 | F6: =IF(OR(E6="",((-Setup!$B$16*(SQRT(3)*((C6-Setup!$B$18)+Setup!$B$27)+(D6-Setup!$B$19)+Setup!$B$28))^2+(2*(E6-Setup!$B$20)*Setup!$B$16)^2-(((C6-Setup!$B$18)^2+(D6-Setup!$B$19)^2+(E6-Setup!$B$20)^2)+Setup!$B$27^2+Setup!$B$28^2+Setup!$B$16^2+2*(C6-Setup!$B$18)*Setup!$B$27+2*(D6-Setup!$B$19)*Setup!$B$28-Setup!$B$17^2)^2)<0),"",DEGREES(2*ATAN((-(2*(E6-Setup!$B$20)*Setup!$B$16)-SQRT(((-Setup!$B$16*(SQRT(3)*((C6-Setup!$B$18)+Setup!$B$27)+(D6-Setup!$B$19)+Setup!$B$28))^2+(2*(E6-Setup!$B$20)*Setup!$B$16)^2-(((C6-Setup!$B$18)^2+(D6-Setup!$B$19)^2+(E6-Setup!$B$20)^2)+Setup!$B$27^2+Setup!$B$28^2+Setup!$B$16^2+2*(C6-Setup!$B$18)*Setup!$B$27+2*(D6-Setup!$B$19)*Setup!$B$28-Setup!$B$17^2)^2)))/((((C6-Setup!$B$18)^2+(D6-Setup!$B$19)^2+(E6-Setup!$B$20)^2)+Setup!$B$27^2+Setup!$B$28^2+Setup!$B$16^2+2*(C6-Setup!$B$18)*Setup!$B$27+2*(D6-Setup!$B$19)*Setup!$B$28-Setup!$B$17^2)-(-Setup!$B$16*(SQRT(3)*((C6-Setup!$B$18)+Setup!$B$27)+(D6-Setup!$B$19)+Setup!$B$28)))))) -> 35.435622 | G6: =IF(OR(E6="",((Setup!$B$16*(SQRT(3)*((C6-Setup!$B$18)-Setup!$B$27)-(D6-Setup!$B$19)-Setup!$B$28))^2+(2*(E6-Setup!$B$20)*Setup!$B$16)^2-(((C6-Setup!$B$18)^2+(D6-Setup!$B$19)^2+(E6-Setup!$B$20)^2)+Setup!$B$27^2+Setup!$B$28^2+Setup!$B$16^2-2*(C6-Setup!$B$18)*Setup!$B$27+2*(D6-Setup!$B$19)*Setup!$B$28-Setup!$B$17^2)^2)<0),"",DEGREES(2*ATAN((-(2*(E6-Setup!$B$20)*Setup!$B$16)-SQRT(((Setup!$B$16*(SQRT(3)*((C6-Setup!$B$18)-Setup!$B$27)-(D6-Setup!$B$19)-Setup!$B$28))^2+(2*(E6-Setup!$B$20)*Setup!$B$16)^2-(((C6-Setup!$B$18)^2+(D6-Setup!$B$19)^2+(E6-Setup!$B$20)^2)+Setup!$B$27^2+Setup!$B$28^2+Setup!$B$16^2-2*(C6-Setup!$B$18)*Setup!$B$27+2*(D6-Setup!$B$19)*Setup!$B$28-Setup!$B$17^2)^2)))/((((C6-Setup!$B$18)^2+(D6-Setup!$B$19)^2+(E6-Setup!$B$20)^2)+Setup!$B$27^2+Setup!$B$28^2+Setup!$B$16^2-2*(C6-Setup!$B$18)*Setup!$B$27+2*(D6-Setup!$B$19)*Setup!$B$28-Setup!$B$17^2)-(Setup!$B$16*(SQRT(3)*((C6-Setup!$B$18)-Setup!$B$27)-(D6-Setup!$B$19)-Setup!$B$28)))))) -> 35.435622 | H6: =IF(OR(E6="",((2*Setup!$B$16*((D6-Setup!$B$19)+Setup!$B$26))^2+(2*(E6-Setup!$B$20)*Setup!$B$16)^2-(((C6-Setup!$B$18)^2+(D6-Setup!$B$19)^2+(E6-Setup!$B$20)^2)+Setup!$B$26^2+Setup!$B$16^2+2*(D6-Setup!$B$19)*Setup!$B$26-Setup!$B$17^2)^2)<0),"",DEGREES(2*ATAN((-(2*(E6-Setup!$B$20)*Setup!$B$16)-SQRT(((2*Setup!$B$16*((D6-Setup!$B$19)+Setup!$B$26))^2+(2*(E6-Setup!$B$20)*Setup!$B$16)^2-(((C6-Setup!$B$18)^2+(D6-Setup!$B$19)^2+(E6-Setup!$B$20)^2)+Setup!$B$26^2+Setup!$B$16^2+2*(D6-Setup!$B$19)*Setup!$B$26-Setup!$B$17^2)^2)))/((((C6-Setup!$B$18)^2+(D6-Setup!$B$19)^2+(E6-Setup!$B$20)^2)+Setup!$B$26^2+Setup!$B$16^2+2*(D6-Setup!$B$19)*Setup!$B$26-Setup!$B$17^2)-(2*Setup!$B$16*((D6-Setup!$B$19)+Setup!$B$26)))))) -> 35.435622 | O6: =IF(OR(L6="",F6=""),"",L6-F6) | P6: =IF(OR(M6="",G6=""),"",M6-G6) | Q6: =IF(OR(N6="",H6=""),"",N6-H6)
A7: Rep 2 | B7: 2 | C7: 0 | D7: 0 | E7: -730 | F7: =IF(OR(E7="",((-Setup!$B$16*(SQRT(3)*((C7-Setup!$B$18)+Setup!$B$27)+(D7-Setup!$B$19)+Setup!$B$28))^2+(2*(E7-Setup!$B$20)*Setup!$B$16)^2-(((C7-Setup!$B$18)^2+(D7-Setup!$B$19)^2+(E7-Setup!$B$20)^2)+Setup!$B$27^2+Setup!$B$28^2+Setup!$B$16^2+2*(C7-Setup!$B$18)*Setup!$B$27+2*(D7-Setup!$B$19)*Setup!$B$28-Setup!$B$17^2)^2)<0),"",DEGREES(2*ATAN((-(2*(E7-Setup!$B$20)*Setup!$B$16)-SQRT(((-Setup!$B$16*(SQRT(3)*((C7-Setup!$B$18)+Setup!$B$27)+(D7-Setup!$B$19)+Setup!$B$28))^2+(2*(E7-Setup!$B$20)*Setup!$B$16)^2-(((C7-Setup!$B$18)^2+(D7-Setup!$B$19)^2+(E7-Setup!$B$20)^2)+Setup!$B$27^2+Setup!$B$28^2+Setup!$B$16^2+2*(C7-Setup!$B$18)*Setup!$B$27+2*(D7-Setup!$B$19)*Setup!$B$28-Setup!$B$17^2)^2)))/((((C7-Setup!$B$18)^2+(D7-Setup!$B$19)^2+(E7-Setup!$B$20)^2)+Setup!$B$27^2+Setup!$B$28^2+Setup!$B$16^2+2*(C7-Setup!$B$18)*Setup!$B$27+2*(D7-Setup!$B$19)*Setup!$B$28-Setup!$B$17^2)-(-Setup!$B$16*(SQRT(3)*((C7-Setup!$B$18)+Setup!$B$27)+(D7-Setup!$B$19)+Setup!$B$28)))))) -> 35.435622 | G7: =IF(OR(E7="",((Setup!$B$16*(SQRT(3)*((C7-Setup!$B$18)-Setup!$B$27)-(D7-Setup!$B$19)-Setup!$B$28))^2+(2*(E7-Setup!$B$20)*Setup!$B$16)^2-(((C7-Setup!$B$18)^2+(D7-Setup!$B$19)^2+(E7-Setup!$B$20)^2)+Setup!$B$27^2+Setup!$B$28^2+Setup!$B$16^2-2*(C7-Setup!$B$18)*Setup!$B$27+2*(D7-Setup!$B$19)*Setup!$B$28-Setup!$B$17^2)^2)<0),"",DEGREES(2*ATAN((-(2*(E7-Setup!$B$20)*Setup!$B$16)-SQRT(((Setup!$B$16*(SQRT(3)*((C7-Setup!$B$18)-Setup!$B$27)-(D7-Setup!$B$19)-Setup!$B$28))^2+(2*(E7-Setup!$B$20)*Setup!$B$16)^2-(((C7-Setup!$B$18)^2+(D7-Setup!$B$19)^2+(E7-Setup!$B$20)^2)+Setup!$B$27^2+Setup!$B$28^2+Setup!$B$16^2-2*(C7-Setup!$B$18)*Setup!$B$27+2*(D7-Setup!$B$19)*Setup!$B$28-Setup!$B$17^2)^2)))/((((C7-Setup!$B$18)^2+(D7-Setup!$B$19)^2+(E7-Setup!$B$20)^2)+Setup!$B$27^2+Setup!$B$28^2+Setup!$B$16^2-2*(C7-Setup!$B$18)*Setup!$B$27+2*(D7-Setup!$B$19)*Setup!$B$28-Setup!$B$17^2)-(Setup!$B$16*(SQRT(3)*((C7-Setup!$B$18)-Setup!$B$27)-(D7-Setup!$B$19)-Setup!$B$28)))))) -> 35.435622 | H7: =IF(OR(E7="",((2*Setup!$B$16*((D7-Setup!$B$19)+Setup!$B$26))^2+(2*(E7-Setup!$B$20)*Setup!$B$16)^2-(((C7-Setup!$B$18)^2+(D7-Setup!$B$19)^2+(E7-Setup!$B$20)^2)+Setup!$B$26^2+Setup!$B$16^2+2*(D7-Setup!$B$19)*Setup!$B$26-Setup!$B$17^2)^2)<0),"",DEGREES(2*ATAN((-(2*(E7-Setup!$B$20)*Setup!$B$16)-SQRT(((2*Setup!$B$16*((D7-Setup!$B$19)+Setup!$B$26))^2+(2*(E7-Setup!$B$20)*Setup!$B$16)^2-(((C7-Setup!$B$18)^2+(D7-Setup!$B$19)^2+(E7-Setup!$B$20)^2)+Setup!$B$26^2+Setup!$B$16^2+2*(D7-Setup!$B$19)*Setup!$B$26-Setup!$B$17^2)^2)))/((((C7-Setup!$B$18)^2+(D7-Setup!$B$19)^2+(E7-Setup!$B$20)^2)+Setup!$B$26^2+Setup!$B$16^2+2*(D7-Setup!$B$19)*Setup!$B$26-Setup!$B$17^2)-(2*Setup!$B$16*((D7-Setup!$B$19)+Setup!$B$26)))))) -> 35.435622 | O7: =IF(OR(L7="",F7=""),"",L7-F7) | P7: =IF(OR(M7="",G7=""),"",M7-G7) | Q7: =IF(OR(N7="",H7=""),"",N7-H7)
A8: Rep 3 | B8: 3 | C8: 0 | D8: 0 | E8: -730 | F8: =IF(OR(E8="",((-Setup!$B$16*(SQRT(3)*((C8-Setup!$B$18)+Setup!$B$27)+(D8-Setup!$B$19)+Setup!$B$28))^2+(2*(E8-Setup!$B$20)*Setup!$B$16)^2-(((C8-Setup!$B$18)^2+(D8-Setup!$B$19)^2+(E8-Setup!$B$20)^2)+Setup!$B$27^2+Setup!$B$28^2+Setup!$B$16^2+2*(C8-Setup!$B$18)*Setup!$B$27+2*(D8-Setup!$B$19)*Setup!$B$28-Setup!$B$17^2)^2)<0),"",DEGREES(2*ATAN((-(2*(E8-Setup!$B$20)*Setup!$B$16)-SQRT(((-Setup!$B$16*(SQRT(3)*((C8-Setup!$B$18)+Setup!$B$27)+(D8-Setup!$B$19)+Setup!$B$28))^2+(2*(E8-Setup!$B$20)*Setup!$B$16)^2-(((C8-Setup!$B$18)^2+(D8-Setup!$B$19)^2+(E8-Setup!$B$20)^2)+Setup!$B$27^2+Setup!$B$28^2+Setup!$B$16^2+2*(C8-Setup!$B$18)*Setup!$B$27+2*(D8-Setup!$B$19)*Setup!$B$28-Setup!$B$17^2)^2)))/((((C8-Setup!$B$18)^2+(D8-Setup!$B$19)^2+(E8-Setup!$B$20)^2)+Setup!$B$27^2+Setup!$B$28^2+Setup!$B$16^2+2*(C8-Setup!$B$18)*Setup!$B$27+2*(D8-Setup!$B$19)*Setup!$B$28-Setup!$B$17^2)-(-Setup!$B$16*(SQRT(3)*((C8-Setup!$B$18)+Setup!$B$27)+(D8-Setup!$B$19)+Setup!$B$28)))))) -> 35.435622 | G8: =IF(OR(E8="",((Setup!$B$16*(SQRT(3)*((C8-Setup!$B$18)-Setup!$B$27)-(D8-Setup!$B$19)-Setup!$B$28))^2+(2*(E8-Setup!$B$20)*Setup!$B$16)^2-(((C8-Setup!$B$18)^2+(D8-Setup!$B$19)^2+(E8-Setup!$B$20)^2)+Setup!$B$27^2+Setup!$B$28^2+Setup!$B$16^2-2*(C8-Setup!$B$18)*Setup!$B$27+2*(D8-Setup!$B$19)*Setup!$B$28-Setup!$B$17^2)^2)<0),"",DEGREES(2*ATAN((-(2*(E8-Setup!$B$20)*Setup!$B$16)-SQRT(((Setup!$B$16*(SQRT(3)*((C8-Setup!$B$18)-Setup!$B$27)-(D8-Setup!$B$19)-Setup!$B$28))^2+(2*(E8-Setup!$B$20)*Setup!$B$16)^2-(((C8-Setup!$B$18)^2+(D8-Setup!$B$19)^2+(E8-Setup!$B$20)^2)+Setup!$B$27^2+Setup!$B$28^2+Setup!$B$16^2-2*(C8-Setup!$B$18)*Setup!$B$27+2*(D8-Setup!$B$19)*Setup!$B$28-Setup!$B$17^2)^2)))/((((C8-Setup!$B$18)^2+(D8-Setup!$B$19)^2+(E8-Setup!$B$20)^2)+Setup!$B$27^2+Setup!$B$28^2+Setup!$B$16^2-2*(C8-Setup!$B$18)*Setup!$B$27+2*(D8-Setup!$B$19)*Setup!$B$28-Setup!$B$17^2)-(Setup!$B$16*(SQRT(3)*((C8-Setup!$B$18)-Setup!$B$27)-(D8-Setup!$B$19)-Setup!$B$28)))))) -> 35.435622 | H8: =IF(OR(E8="",((2*Setup!$B$16*((D8-Setup!$B$19)+Setup!$B$26))^2+(2*(E8-Setup!$B$20)*Setup!$B$16)^2-(((C8-Setup!$B$18)^2+(D8-Setup!$B$19)^2+(E8-Setup!$B$20)^2)+Setup!$B$26^2+Setup!$B$16^2+2*(D8-Setup!$B$19)*Setup!$B$26-Setup!$B$17^2)^2)<0),"",DEGREES(2*ATAN((-(2*(E8-Setup!$B$20)*Setup!$B$16)-SQRT(((2*Setup!$B$16*((D8-Setup!$B$19)+Setup!$B$26))^2+(2*(E8-Setup!$B$20)*Setup!$B$16)^2-(((C8-Setup!$B$18)^2+(D8-Setup!$B$19)^2+(E8-Setup!$B$20)^2)+Setup!$B$26^2+Setup!$B$16^2+2*(D8-Setup!$B$19)*Setup!$B$26-Setup!$B$17^2)^2)))/((((C8-Setup!$B$18)^2+(D8-Setup!$B$19)^2+(E8-Setup!$B$20)^2)+Setup!$B$26^2+Setup!$B$16^2+2*(D8-Setup!$B$19)*Setup!$B$26-Setup!$B$17^2)-(2*Setup!$B$16*((D8-Setup!$B$19)+Setup!$B$26)))))) -> 35.435622 | O8: =IF(OR(L8="",F8=""),"",L8-F8) | P8: =IF(OR(M8="",G8=""),"",M8-G8) | Q8: =IF(OR(N8="",H8=""),"",N8-H8)
A9: Rep 1 | B9: 4 | C9: 0 | D9: 0 | E9: -650 | F9: =IF(OR(E9="",((-Setup!$B$16*(SQRT(3)*((C9-Setup!$B$18)+Setup!$B$27)+(D9-Setup!$B$19)+Setup!$B$28))^2+(2*(E9-Setup!$B$20)*Setup!$B$16)^2-(((C9-Setup!$B$18)^2+(D9-Setup!$B$19)^2+(E9-Setup!$B$20)^2)+Setup!$B$27^2+Setup!$B$28^2+Setup!$B$16^2+2*(C9-Setup!$B$18)*Setup!$B$27+2*(D9-Setup!$B$19)*Setup!$B$28-Setup!$B$17^2)^2)<0),"",DEGREES(2*ATAN((-(2*(E9-Setup!$B$20)*Setup!$B$16)-SQRT(((-Setup!$B$16*(SQRT(3)*((C9-Setup!$B$18)+Setup!$B$27)+(D9-Setup!$B$19)+Setup!$B$28))^2+(2*(E9-Setup!$B$20)*Setup!$B$16)^2-(((C9-Setup!$B$18)^2+(D9-Setup!$B$19)^2+(E9-Setup!$B$20)^2)+Setup!$B$27^2+Setup!$B$28^2+Setup!$B$16^2+2*(C9-Setup!$B$18)*Setup!$B$27+2*(D9-Setup!$B$19)*Setup!$B$28-Setup!$B$17^2)^2)))/((((C9-Setup!$B$18)^2+(D9-Setup!$B$19)^2+(E9-Setup!$B$20)^2)+Setup!$B$27^2+Setup!$B$28^2+Setup!$B$16^2+2*(C9-Setup!$B$18)*Setup!$B$27+2*(D9-Setup!$B$19)*Setup!$B$28-Setup!$B$17^2)-(-Setup!$B$16*(SQRT(3)*((C9-Setup!$B$18)+Setup!$B$27)+(D9-Setup!$B$19)+Setup!$B$28)))))) -> 10.064544 | G9: =IF(OR(E9="",((Setup!$B$16*(SQRT(3)*((C9-Setup!$B$18)-Setup!$B$27)-(D9-Setup!$B$19)-Setup!$B$28))^2+(2*(E9-Setup!$B$20)*Setup!$B$16)^2-(((C9-Setup!$B$18)^2+(D9-Setup!$B$19)^2+(E9-Setup!$B$20)^2)+Setup!$B$27^2+Setup!$B$28^2+Setup!$B$16^2-2*(C9-Setup!$B$18)*Setup!$B$27+2*(D9-Setup!$B$19)*Setup!$B$28-Setup!$B$17^2)^2)<0),"",DEGREES(2*ATAN((-(2*(E9-Setup!$B$20)*Setup!$B$16)-SQRT(((Setup!$B$16*(SQRT(3)*((C9-Setup!$B$18)-Setup!$B$27)-(D9-Setup!$B$19)-Setup!$B$28))^2+(2*(E9-Setup!$B$20)*Setup!$B$16)^2-(((C9-Setup!$B$18)^2+(D9-Setup!$B$19)^2+(E9-Setup!$B$20)^2)+Setup!$B$27^2+Setup!$B$28^2+Setup!$B$16^2-2*(C9-Setup!$B$18)*Setup!$B$27+2*(D9-Setup!$B$19)*Setup!$B$28-Setup!$B$17^2)^2)))/((((C9-Setup!$B$18)^2+(D9-Setup!$B$19)^2+(E9-Setup!$B$20)^2)+Setup!$B$27^2+Setup!$B$28^2+Setup!$B$16^2-2*(C9-Setup!$B$18)*Setup!$B$27+2*(D9-Setup!$B$19)*Setup!$B$28-Setup!$B$17^2)-(Setup!$B$16*(SQRT(3)*((C9-Setup!$B$18)-Setup!$B$27)-(D9-Setup!$B$19)-Setup!$B$28)))))) -> 10.064544 | H9: =IF(OR(E9="",((2*Setup!$B$16*((D9-Setup!$B$19)+Setup!$B$26))^2+(2*(E9-Setup!$B$20)*Setup!$B$16)^2-(((C9-Setup!$B$18)^2+(D9-Setup!$B$19)^2+(E9-Setup!$B$20)^2)+Setup!$B$26^2+Setup!$B$16^2+2*(D9-Setup!$B$19)*Setup!$B$26-Setup!$B$17^2)^2)<0),"",DEGREES(2*ATAN((-(2*(E9-Setup!$B$20)*Setup!$B$16)-SQRT(((2*Setup!$B$16*((D9-Setup!$B$19)+Setup!$B$26))^2+(2*(E9-Setup!$B$20)*Setup!$B$16)^2-(((C9-Setup!$B$18)^2+(D9-Setup!$B$19)^2+(E9-Setup!$B$20)^2)+Setup!$B$26^2+Setup!$B$16^2+2*(D9-Setup!$B$19)*Setup!$B$26-Setup!$B$17^2)^2)))/((((C9-Setup!$B$18)^2+(D9-Setup!$B$19)^2+(E9-Setup!$B$20)^2)+Setup!$B$26^2+Setup!$B$16^2+2*(D9-Setup!$B$19)*Setup!$B$26-Setup!$B$17^2)-(2*Setup!$B$16*((D9-Setup!$B$19)+Setup!$B$26)))))) -> 10.064544 | O9: =IF(OR(L9="",F9=""),"",L9-F9) | P9: =IF(OR(M9="",G9=""),"",M9-G9) | Q9: =IF(OR(N9="",H9=""),"",N9-H9)
A10: Rep 2 | B10: 5 | C10: 0 | D10: 0 | E10: -650 | F10: =IF(OR(E10="",((-Setup!$B$16*(SQRT(3)*((C10-Setup!$B$18)+Setup!$B$27)+(D10-Setup!$B$19)+Setup!$B$28))^2+(2*(E10-Setup!$B$20)*Setup!$B$16)^2-(((C10-Setup!$B$18)^2+(D10-Setup!$B$19)^2+(E10-Setup!$B$20)^2)+Setup!$B$27^2+Setup!$B$28^2+Setup!$B$16^2+2*(C10-Setup!$B$18)*Setup!$B$27+2*(D10-Setup!$B$19)*Setup!$B$28-Setup!$B$17^2)^2)<0),"",DEGREES(2*ATAN((-(2*(E10-Setup!$B$20)*Setup!$B$16)-SQRT(((-Setup!$B$16*(SQRT(3)*((C10-Setup!$B$18)+Setup!$B$27)+(D10-Setup!$B$19)+Setup!$B$28))^2+(2*(E10-Setup!$B$20)*Setup!$B$16)^2-(((C10-Setup!$B$18)^2+(D10-Setup!$B$19)^2+(E10-Setup!$B$20)^2)+Setup!$B$27^2+Setup!$B$28^2+Setup!$B$16^2+2*(C10-Setup!$B$18)*Setup!$B$27+2*(D10-Setup!$B$19)*Setup!$B$28-Setup!$B$17^2)^2)))/((((C10-Setup!$B$18)^2+(D10-Setup!$B$19)^2+(E10-Setup!$B$20)^2)+Setup!$B$27^2+Setup!$B$28^2+Setup!$B$16^2+2*(C10-Setup!$B$18)*Setup!$B$27+2*(D10-Setup!$B$19)*Setup!$B$28-Setup!$B$17^2)-(-Setup!$B$16*(SQRT(3)*((C10-Setup!$B$18)+Setup!$B$27)+(D10-Setup!$B$19)+Setup!$B$28)))))) -> 10.064544 | G10: =IF(OR(E10="",((Setup!$B$16*(SQRT(3)*((C10-Setup!$B$18)-Setup!$B$27)-(D10-Setup!$B$19)-Setup!$B$28))^2+(2*(E10-Setup!$B$20)*Setup!$B$16)^2-(((C10-Setup!$B$18)^2+(D10-Setup!$B$19)^2+(E10-Setup!$B$20)^2)+Setup!$B$27^2+Setup!$B$28^2+Setup!$B$16^2-2*(C10-Setup!$B$18)*Setup!$B$27+2*(D10-Setup!$B$19)*Setup!$B$28-Setup!$B$17^2)^2)<0),"",DEGREES(2*ATAN((-(2*(E10-Setup!$B$20)*Setup!$B$16)-SQRT(((Setup!$B$16*(SQRT(3)*((C10-Setup!$B$18)-Setup!$B$27)-(D10-Setup!$B$19)-Setup!$B$28))^2+(2*(E10-Setup!$B$20)*Setup!$B$16)^2-(((C10-Setup!$B$18)^2+(D10-Setup!$B$19)^2+(E10-Setup!$B$20)^2)+Setup!$B$27^2+Setup!$B$28^2+Setup!$B$16^2-2*(C10-Setup!$B$18)*Setup!$B$27+2*(D10-Setup!$B$19)*Setup!$B$28-Setup!$B$17^2)^2)))/((((C10-Setup!$B$18)^2+(D10-Setup!$B$19)^2+(E10-Setup!$B$20)^2)+Setup!$B$27^2+Setup!$B$28^2+Setup!$B$16^2-2*(C10-Setup!$B$18)*Setup!$B$27+2*(D10-Setup!$B$19)*Setup!$B$28-Setup!$B$17^2)-(Setup!$B$16*(SQRT(3)*((C10-Setup!$B$18)-Setup!$B$27)-(D10-Setup!$B$19)-Setup!$B$28)))))) -> 10.064544 | H10: =IF(OR(E10="",((2*Setup!$B$16*((D10-Setup!$B$19)+Setup!$B$26))^2+(2*(E10-Setup!$B$20)*Setup!$B$16)^2-(((C10-Setup!$B$18)^2+(D10-Setup!$B$19)^2+(E10-Setup!$B$20)^2)+Setup!$B$26^2+Setup!$B$16^2+2*(D10-Setup!$B$19)*Setup!$B$26-Setup!$B$17^2)^2)<0),"",DEGREES(2*ATAN((-(2*(E10-Setup!$B$20)*Setup!$B$16)-SQRT(((2*Setup!$B$16*((D10-Setup!$B$19)+Setup!$B$26))^2+(2*(E10-Setup!$B$20)*Setup!$B$16)^2-(((C10-Setup!$B$18)^2+(D10-Setup!$B$19)^2+(E10-Setup!$B$20)^2)+Setup!$B$26^2+Setup!$B$16^2+2*(D10-Setup!$B$19)*Setup!$B$26-Setup!$B$17^2)^2)))/((((C10-Setup!$B$18)^2+(D10-Setup!$B$19)^2+(E10-Setup!$B$20)^2)+Setup!$B$26^2+Setup!$B$16^2+2*(D10-Setup!$B$19)*Setup!$B$26-Setup!$B$17^2)-(2*Setup!$B$16*((D10-Setup!$B$19)+Setup!$B$26)))))) -> 10.064544 | O10: =IF(OR(L10="",F10=""),"",L10-F10) | P10: =IF(OR(M10="",G10=""),"",M10-G10) | Q10: =IF(OR(N10="",H10=""),"",N10-H10)
